Workbook

Sheet ZEMERRA
C3: =MID(CELL("filename",A2),SEARCH("[",CELL("filename",A2))+1,SEARCH(".",CELL("filename",A2))-1-SEARCH("[",CELL("filename",A2))) -> #VALUE!
C4: Sub.Ctg :- | E4: GEN | F4: Casting Pcs :- | H4: 1 | J4: Dia Pcs | K4: =G39/E6 -> 10.890185
C5: Metal | D5: 18k | E5: 3.31 | F5: 9kt | G5: =E5*0.75 -> 2.4825 | H5: DV | J5: Dia Wt | K5: =H39/E6 -> 0.49884072 | P5: Tikali
D6: 14k | E6: =E5*0.86 -> 2.8466 | F6: Silver | G6: =E5*0.7 -> 2.317
D7: Platinum950 | F7: =E5*1.45 -> 4.7995 | P7: Shaph | Q7: OD | R7: ID | S7: Pcs
C8: SHAPE | D8: SIEVE SIZE | E8: MM SIZE | F8: PTS | G8: QTY. | H8: WEIGHT
D9: =IF(C9="RNDTRD",INDEX(DIAMOND!$B$9:$C$102,MATCH(E9,DIAMOND!$C$9:$C$102,0),1),IF(C9="RND",INDEX(DIAMOND!$B$9:$C$102,MATCH(E9,DIAMOND!$C$9:$C$102,0),1),IF(C9="PRI",INDEX(DIAMOND!$M$9:$N$63,MATCH(E9,DIAMOND!$N$9:$N$63,0),1),IF(C9="MRQ",INDEX(DIAMOND!$S$40:$T$58,MATCH(E9,DIAMOND!$T$40:$T$58,0),1),IF(C9="PRS",INDEX(DIAMOND!$S$9:$T$35,MATCH(E9,DIAMOND!$T$9:$T$63,0),1),0))))) -> 0 | F9: =IF(C9="RNDTRD",VLOOKUP(E9,DIAMOND!$C$9:$D$102,2,0),IF(C9="RND",VLOOKUP(E9,DIAMOND!$C$9:$D$102,2,0),IF(C9="MRQ",VLOOKUP(E9,DIAMOND!$T$40:$U$58,2,0),IF(C9="PRI",VLOOKUP(E9,DIAMOND!$N$9:$O$63,2,0),IF(C9="PRITRD",VLOOKUP(E9,DIAMOND!$N$9:$O$63,2,0),IF(C9="BUG",VLOOKUP(E9,DIAMOND!$H$9:$I$45,2,0),IF(C9="BUGTRD",VLOOKUP(E9,DIAMOND!$H$9:$I$45,2,0),IF(C9="TAPTRD",VLOOKUP(E9,DIAMOND!$H$9:$I$45,2,0),IF(C9="TAP",VLOOKUP(E9,DIAMOND!$H$9:$I$45,2,0),IF(C9="PRS",VLOOKUP(E9,DIAMOND!$T$9:$U$35,2,0),IF(C9="OVL",VLOOKUP(E9,DIAMOND!$T$64:$U$82,2,0),IF(C9="EMR",VLOOKUP(E9,DIAMOND!$N$69:$O$83,2,0),0)))))))))))) -> 0 | H9: =G9*F9 -> 0
C10: RND | D10: =IF(C10="RNDTRD",INDEX(DIAMOND!$B$9:$C$102,MATCH(E10,DIAMOND!$C$9:$C$102,0),1),IF(C10="RND",INDEX(DIAMOND!$B$9:$C$102,MATCH(E10,DIAMOND!$C$9:$C$102,0),1),IF(C10="PRI",INDEX(DIAMOND!$M$9:$N$63,MATCH(E10,DIAMOND!$N$9:$N$63,0),1),IF(C10="MRQ",INDEX(DIAMOND!$S$40:$T$58,MATCH(E10,DIAMOND!$T$40:$T$58,0),1),IF(C10="PRS",INDEX(DIAMOND!$S$9:$T$35,MATCH(E10,DIAMOND!$T$9:$T$63,0),1),0))))) -> +2.5-3.0 | E10: 1.3 | F10: =IF(C10="RNDTRD",VLOOKUP(E10,DIAMOND!$C$9:$D$102,2,0),IF(C10="RND",VLOOKUP(E10,DIAMOND!$C$9:$D$102,2,0),IF(C10="MRQ",VLOOKUP(E10,DIAMOND!$T$40:$U$58,2,0),IF(C10="PRI",VLOOKUP(E10,DIAMOND!$N$9:$O$63,2,0),IF(C10="PRITRD",VLOOKUP(E10,DIAMOND!$N$9:$O$63,2,0),IF(C10="BUG",VLOOKUP(E10,DIAMOND!$H$9:$I$45,2,0),IF(C10="BUGTRD",VLOOKUP(E10,DIAMOND!$H$9:$I$45,2,0),IF(C10="TAPTRD",VLOOKUP(E10,DIAMOND!$H$9:$I$45,2,0),IF(C10="TAP",VLOOKUP(E10,DIAMOND!$H$9:$I$45,2,0),IF(C10="PRS",VLOOKUP(E10,DIAMOND!$T$9:$U$35,2,0),IF(C10="OVL",VLOOKUP(E10,DIAMOND!$T$64:$U$82,2,0),IF(C10="EMR",VLOOKUP(E10,DIAMOND!$N$69:$O$83,2,0),0)))))))))))) -> 0.01 | G10: 18 | H10: =G10*F10 -> 0.18
C11: RND | D11: =IF(C11="RNDTRD",INDEX(DIAMOND!$B$9:$C$102,MATCH(E11,DIAMOND!$C$9:$C$102,0),1),IF(C11="RND",INDEX(DIAMOND!$B$9:$C$102,MATCH(E11,DIAMOND!$C$9:$C$102,0),1),IF(C11="PRI",INDEX(DIAMOND!$M$9:$N$63,MATCH(E11,DIAMOND!$N$9:$N$63,0),1),IF(C11="MRQ",INDEX(DIAMOND!$S$40:$T$58,MATCH(E11,DIAMOND!$T$40:$T$58,0),1),IF(C11="PRS",INDEX(DIAMOND!$S$9:$T$35,MATCH(E11,DIAMOND!$T$9:$T$63,0),1),0))))) -> +6.0-6.5 | E11: 1.7 | F11: =IF(C11="RNDTRD",VLOOKUP(E11,DIAMOND!$C$9:$D$102,2,0),IF(C11="RND",VLOOKUP(E11,DIAMOND!$C$9:$D$102,2,0),IF(C11="MRQ",VLOOKUP(E11,DIAMOND!$T$40:$U$58,2,0),IF(C11="PRI",VLOOKUP(E11,DIAMOND!$N$9:$O$63,2,0),IF(C11="PRITRD",VLOOKUP(E11,DIAMOND!$N$9:$O$63,2,0),IF(C11="BUG",VLOOKUP(E11,DIAMOND!$H$9:$I$45,2,0),IF(C11="BUGTRD",VLOOKUP(E11,DIAMOND!$H$9:$I$45,2,0),IF(C11="TAPTRD",VLOOKUP(E11,DIAMOND!$H$9:$I$45,2,0),IF(C11="TAP",VLOOKUP(E11,DIAMOND!$H$9:$I$45,2,0),IF(C11="PRS",VLOOKUP(E11,DIAMOND!$T$9:$U$35,2,0),IF(C11="OVL",VLOOKUP(E11,DIAMOND!$T$64:$U$82,2,0),IF(C11="EMR",VLOOKUP(E11,DIAMOND!$N$69:$O$83,2,0),0)))))))))))) -> 0.02 | G11: 12 | H11: =G11*F11 -> 0.24
C12: EMR | D12: =IF(C12="RNDTRD",INDEX(DIAMOND!$B$9:$C$102,MATCH(E12,DIAMOND!$C$9:$C$102,0),1),IF(C12="RND",INDEX(DIAMOND!$B$9:$C$102,MATCH(E12,DIAMOND!$C$9:$C$102,0),1),IF(C12="PRI",INDEX(DIAMOND!$M$9:$N$63,MATCH(E12,DIAMOND!$N$9:$N$63,0),1),IF(C12="MRQ",INDEX(DIAMOND!$S$40:$T$58,MATCH(E12,DIAMOND!$T$40:$T$58,0),1),IF(C12="PRS",INDEX(DIAMOND!$S$9:$T$35,MATCH(E12,DIAMOND!$T$9:$T$63,0),1),0))))) -> 0 | E12: 7X5 | F12: =IF(C12="RNDTRD",VLOOKUP(E12,DIAMOND!$C$9:$D$102,2,0),IF(C12="RND",VLOOKUP(E12,DIAMOND!$C$9:$D$102,2,0),IF(C12="MRQ",VLOOKUP(E12,DIAMOND!$T$40:$U$58,2,0),IF(C12="PRI",VLOOKUP(E12,DIAMOND!$N$9:$O$63,2,0),IF(C12="PRITRD",VLOOKUP(E12,DIAMOND!$N$9:$O$63,2,0),IF(C12="BUG",VLOOKUP(E12,DIAMOND!$H$9:$I$45,2,0),IF(C12="BUGTRD",VLOOKUP(E12,DIAMOND!$H$9:$I$45,2,0),IF(C12="TAPTRD",VLOOKUP(E12,DIAMOND!$H$9:$I$45,2,0),IF(C12="TAP",VLOOKUP(E12,DIAMOND!$H$9:$I$45,2,0),IF(C12="PRS",VLOOKUP(E12,DIAMOND!$T$9:$U$35,2,0),IF(C12="OVL",VLOOKUP(E12,DIAMOND!$T$64:$U$82,2,0),IF(C12="EMR",VLOOKUP(E12,DIAMOND!$N$69:$O$83,2,0),0)))))))))))) -> 1 | G12: 1 | H12: =G12*F12 -> 1
C13: RND | D13: =IF(C13="RNDTRD",INDEX(DIAMOND!$B$9:$C$102,MATCH(E13,DIAMOND!$C$9:$C$102,0),1),IF(C13="RND",INDEX(DIAMOND!$B$9:$C$102,MATCH(E13,DIAMOND!$C$9:$C$102,0),1),IF(C13="PRI",INDEX(DIAMOND!$M$9:$N$63,MATCH(E13,DIAMOND!$N$9:$N$63,0),1),IF(C13="MRQ",INDEX(DIAMOND!$S$40:$T$58,MATCH(E13,DIAMOND!$T$40:$T$58,0),1),IF(C13="PRS",INDEX(DIAMOND!$S$9:$T$35,MATCH(E13,DIAMOND!$T$9:$T$63,0),1),0))))) -> #N/A | F13: =IF(C13="RNDTRD",VLOOKUP(E13,DIAMOND!$C$9:$D$102,2,0),IF(C13="RND",VLOOKUP(E13,DIAMOND!$C$9:$D$102,2,0),IF(C13="MRQ",VLOOKUP(E13,DIAMOND!$T$40:$U$58,2,0),IF(C13="PRI",VLOOKUP(E13,DIAMOND!$N$9:$O$63,2,0),IF(C13="PRITRD",VLOOKUP(E13,DIAMOND!$N$9:$O$63,2,0),IF(C13="BUG",VLOOKUP(E13,DIAMOND!$H$9:$I$45,2,0),IF(C13="BUGTRD",VLOOKUP(E13,DIAMOND!$H$9:$I$45,2,0),IF(C13="TAPTRD",VLOOKUP(E13,DIAMOND!$H$9:$I$45,2,0),IF(C13="TAP",VLOOKUP(E13,DIAMOND!$H$9:$I$45,2,0),IF(C13="PRS",VLOOKUP(E13,DIAMOND!$T$9:$U$35,2,0),IF(C13="OVL",VLOOKUP(E13,DIAMOND!$T$64:$U$82,2,0),IF(C13="EMR",VLOOKUP(E13,DIAMOND!$N$69:$O$83,2,0),0)))))))))))) -> #N/A | H13: =G13*F13 -> #N/A
C14: RND | D14: =IF(C14="RNDTRD",INDEX(DIAMOND!$B$9:$C$102,MATCH(E14,DIAMOND!$C$9:$C$102,0),1),IF(C14="RND",INDEX(DIAMOND!$B$9:$C$102,MATCH(E14,DIAMOND!$C$9:$C$102,0),1),IF(C14="PRI",INDEX(DIAMOND!$M$9:$N$63,MATCH(E14,DIAMOND!$N$9:$N$63,0),1),IF(C14="MRQ",INDEX(DIAMOND!$S$40:$T$58,MATCH(E14,DIAMOND!$T$40:$T$58,0),1),IF(C14="PRS",INDEX(DIAMOND!$S$9:$T$35,MATCH(E14,DIAMOND!$T$9:$T$63,0),1),0))))) -> #N/A | F14: =IF(C14="RNDTRD",VLOOKUP(E14,DIAMOND!$C$9:$D$102,2,0),IF(C14="RND",VLOOKUP(E14,DIAMOND!$C$9:$D$102,2,0),IF(C14="MRQ",VLOOKUP(E14,DIAMOND!$T$40:$U$58,2,0),IF(C14="PRI",VLOOKUP(E14,DIAMOND!$N$9:$O$63,2,0),IF(C14="PRITRD",VLOOKUP(E14,DIAMOND!$N$9:$O$63,2,0),IF(C14="BUG",VLOOKUP(E14,DIAMOND!$H$9:$I$45,2,0),IF(C14="BUGTRD",VLOOKUP(E14,DIAMOND!$H$9:$I$45,2,0),IF(C14="TAPTRD",VLOOKUP(E14,DIAMOND!$H$9:$I$45,2,0),IF(C14="TAP",VLOOKUP(E14,DIAMOND!$H$9:$I$45,2,0),IF(C14="PRS",VLOOKUP(E14,DIAMOND!$T$9:$U$35,2,0),IF(C14="OVL",VLOOKUP(E14,DIAMOND!$T$64:$U$82,2,0),IF(C14="EMR",VLOOKUP(E14,DIAMOND!$N$69:$O$83,2,0),0)))))))))))) -> #N/A | H14: =G14*F14 -> #N/A
C15: RND | D15: =IF(C15="RNDTRD",INDEX(DIAMOND!$B$9:$C$102,MATCH(E15,DIAMOND!$C$9:$C$102,0),1),IF(C15="RND",INDEX(DIAMOND!$B$9:$C$102,MATCH(E15,DIAMOND!$C$9:$C$102,0),1),IF(C15="PRI",INDEX(DIAMOND!$M$9:$N$63,MATCH(E15,DIAMOND!$N$9:$N$63,0),1),IF(C15="MRQ",INDEX(DIAMOND!$S$40:$T$58,MATCH(E15,DIAMOND!$T$40:$T$58,0),1),IF(C15="PRS",INDEX(DIAMOND!$S$9:$T$35,MATCH(E15,DIAMOND!$T$9:$T$63,0),1),0))))) -> #N/A | F15: =IF(C15="RNDTRD",VLOOKUP(E15,DIAMOND!$C$9:$D$102,2,0),IF(C15="RND",VLOOKUP(E15,DIAMOND!$C$9:$D$102,2,0),IF(C15="MRQ",VLOOKUP(E15,DIAMOND!$T$40:$U$58,2,0),IF(C15="PRI",VLOOKUP(E15,DIAMOND!$N$9:$O$63,2,0),IF(C15="PRITRD",VLOOKUP(E15,DIAMOND!$N$9:$O$63,2,0),IF(C15="BUG",VLOOKUP(E15,DIAMOND!$H$9:$I$45,2,0),IF(C15="BUGTRD",VLOOKUP(E15,DIAMOND!$H$9:$I$45,2,0),IF(C15="TAPTRD",VLOOKUP(E15,DIAMOND!$H$9:$I$45,2,0),IF(C15="TAP",VLOOKUP(E15,DIAMOND!$H$9:$I$45,2,0),IF(C15="PRS",VLOOKUP(E15,DIAMOND!$T$9:$U$35,2,0),IF(C15="OVL",VLOOKUP(E15,DIAMOND!$T$64:$U$82,2,0),IF(C15="EMR",VLOOKUP(E15,DIAMOND!$N$69:$O$83,2,0),0)))))))))))) -> #N/A | H15: =G15*F15 -> #N/A
C16: RND | D16: =IF(C16="RNDTRD",INDEX(DIAMOND!$B$9:$C$102,MATCH(E16,DIAMOND!$C$9:$C$102,0),1),IF(C16="RND",INDEX(DIAMOND!$B$9:$C$102,MATCH(E16,DIAMOND!$C$9:$C$102,0),1),IF(C16="PRI",INDEX(DIAMOND!$M$9:$N$63,MATCH(E16,DIAMOND!$N$9:$N$63,0),1),IF(C16="MRQ",INDEX(DIAMOND!$S$40:$T$58,MATCH(E16,DIAMOND!$T$40:$T$58,0),1),IF(C16="PRS",INDEX(DIAMOND!$S$9:$T$35,MATCH(E16,DIAMOND!$T$9:$T$63,0),1),0))))) -> #N/A | F16: =IF(C16="RNDTRD",VLOOKUP(E16,DIAMOND!$C$9:$D$102,2,0),IF(C16="RND",VLOOKUP(E16,DIAMOND!$C$9:$D$102,2,0),IF(C16="MRQ",VLOOKUP(E16,DIAMOND!$T$40:$U$58,2,0),IF(C16="PRI",VLOOKUP(E16,DIAMOND!$N$9:$O$63,2,0),IF(C16="PRITRD",VLOOKUP(E16,DIAMOND!$N$9:$O$63,2,0),IF(C16="BUG",VLOOKUP(E16,DIAMOND!$H$9:$I$45,2,0),IF(C16="BUGTRD",VLOOKUP(E16,DIAMOND!$H$9:$I$45,2,0),IF(C16="TAPTRD",VLOOKUP(E16,DIAMOND!$H$9:$I$45,2,0),IF(C16="TAP",VLOOKUP(E16,DIAMOND!$H$9:$I$45,2,0),IF(C16="PRS",VLOOKUP(E16,DIAMOND!$T$9:$U$35,2,0),IF(C16="OVL",VLOOKUP(E16,DIAMOND!$T$64:$U$82,2,0),IF(C16="EMR",VLOOKUP(E16,DIAMOND!$N$69:$O$83,2,0),0)))))))))))) -> #N/A | H16: =G16*F16 -> #N/A
C17: RND | D17: =IF(C17="RNDTRD",INDEX(DIAMOND!$B$9:$C$102,MATCH(E17,DIAMOND!$C$9:$C$102,0),1),IF(C17="RND",INDEX(DIAMOND!$B$9:$C$102,MATCH(E17,DIAMOND!$C$9:$C$102,0),1),IF(C17="PRI",INDEX(DIAMOND!$M$9:$N$63,MATCH(E17,DIAMOND!$N$9:$N$63,0),1),IF(C17="MRQ",INDEX(DIAMOND!$S$40:$T$58,MATCH(E17,DIAMOND!$T$40:$T$58,0),1),IF(C17="PRS",INDEX(DIAMOND!$S$9:$T$35,MATCH(E17,DIAMOND!$T$9:$T$63,0),1),0))))) -> #N/A | F17: =IF(C17="RNDTRD",VLOOKUP(E17,DIAMOND!$C$9:$D$102,2,0),IF(C17="RND",VLOOKUP(E17,DIAMOND!$C$9:$D$102,2,0),IF(C17="MRQ",VLOOKUP(E17,DIAMOND!$T$40:$U$58,2,0),IF(C17="PRI",VLOOKUP(E17,DIAMOND!$N$9:$O$63,2,0),IF(C17="PRITRD",VLOOKUP(E17,DIAMOND!$N$9:$O$63,2,0),IF(C17="BUG",VLOOKUP(E17,DIAMOND!$H$9:$I$45,2,0),IF(C17="BUGTRD",VLOOKUP(E17,DIAMOND!$H$9:$I$45,2,0),IF(C17="TAPTRD",VLOOKUP(E17,DIAMOND!$H$9:$I$45,2,0),IF(C17="TAP",VLOOKUP(E17,DIAMOND!$H$9:$I$45,2,0),IF(C17="PRS",VLOOKUP(E17,DIAMOND!$T$9:$U$35,2,0),IF(C17="OVL",VLOOKUP(E17,DIAMOND!$T$64:$U$82,2,0),IF(C17="EMR",VLOOKUP(E17,DIAMOND!$N$69:$O$83,2,0),0)))))))))))) -> #N/A | H17: =G17*F17 -> #N/A
C18: RND | D18: =IF(C18="RNDTRD",INDEX(DIAMOND!$B$9:$C$102,MATCH(E18,DIAMOND!$C$9:$C$102,0),1),IF(C18="RND",INDEX(DIAMOND!$B$9:$C$102,MATCH(E18,DIAMOND!$C$9:$C$102,0),1),IF(C18="PRI",INDEX(DIAMOND!$M$9:$N$63,MATCH(E18,DIAMOND!$N$9:$N$63,0),1),IF(C18="MRQ",INDEX(DIAMOND!$S$40:$T$58,MATCH(E18,DIAMOND!$T$40:$T$58,0),1),IF(C18="PRS",INDEX(DIAMOND!$S$9:$T$35,MATCH(E18,DIAMOND!$T$9:$T$63,0),1),0))))) -> #N/A | F18: =IF(C18="RNDTRD",VLOOKUP(E18,DIAMOND!$C$9:$D$102,2,0),IF(C18="RND",VLOOKUP(E18,DIAMOND!$C$9:$D$102,2,0),IF(C18="MRQ",VLOOKUP(E18,DIAMOND!$T$40:$U$58,2,0),IF(C18="PRI",VLOOKUP(E18,DIAMOND!$N$9:$O$63,2,0),IF(C18="PRITRD",VLOOKUP(E18,DIAMOND!$N$9:$O$63,2,0),IF(C18="BUG",VLOOKUP(E18,DIAMOND!$H$9:$I$45,2,0),IF(C18="BUGTRD",VLOOKUP(E18,DIAMOND!$H$9:$I$45,2,0),IF(C18="TAPTRD",VLOOKUP(E18,DIAMOND!$H$9:$I$45,2,0),IF(C18="TAP",VLOOKUP(E18,DIAMOND!$H$9:$I$45,2,0),IF(C18="PRS",VLOOKUP(E18,DIAMOND!$T$9:$U$35,2,0),IF(C18="OVL",VLOOKUP(E18,DIAMOND!$T$64:$U$82,2,0),IF(C18="EMR",VLOOKUP(E18,DIAMOND!$N$69:$O$83,2,0),0)))))))))))) -> #N/A | H18: =G18*F18 -> #N/A
C19: RND | D19: =IF(C19="RNDTRD",INDEX(DIAMOND!$B$9:$C$102,MATCH(E19,DIAMOND!$C$9:$C$102,0),1),IF(C19="RND",INDEX(DIAMOND!$B$9:$C$102,MATCH(E19,DIAMOND!$C$9:$C$102,0),1),IF(C19="PRI",INDEX(DIAMOND!$M$9:$N$63,MATCH(E19,DIAMOND!$N$9:$N$63,0),1),IF(C19="MRQ",INDEX(DIAMOND!$S$40:$T$58,MATCH(E19,DIAMOND!$T$40:$T$58,0),1),IF(C19="PRS",INDEX(DIAMOND!$S$9:$T$35,MATCH(E19,DIAMOND!$T$9:$T$63,0),1),0))))) -> #N/A | F19: =IF(C19="RNDTRD",VLOOKUP(E19,DIAMOND!$C$9:$D$102,2,0),IF(C19="RND",VLOOKUP(E19,DIAMOND!$C$9:$D$102,2,0),IF(C19="MRQ",VLOOKUP(E19,DIAMOND!$T$40:$U$58,2,0),IF(C19="PRI",VLOOKUP(E19,DIAMOND!$N$9:$O$63,2,0),IF(C19="PRITRD",VLOOKUP(E19,DIAMOND!$N$9:$O$63,2,0),IF(C19="BUG",VLOOKUP(E19,DIAMOND!$H$9:$I$45,2,0),IF(C19="BUGTRD",VLOOKUP(E19,DIAMOND!$H$9:$I$45,2,0),IF(C19="TAPTRD",VLOOKUP(E19,DIAMOND!$H$9:$I$45,2,0),IF(C19="TAP",VLOOKUP(E19,DIAMOND!$H$9:$I$45,2,0),IF(C19="PRS",VLOOKUP(E19,DIAMOND!$T$9:$U$35,2,0),IF(C19="OVL",VLOOKUP(E19,DIAMOND!$T$64:$U$82,2,0),IF(C19="EMR",VLOOKUP(E19,DIAMOND!$N$69:$O$83,2,0),0)))))))))))) -> #N/A | H19: =G19*F19 -> #N/A
D20: =IF(C20="RNDTRD",INDEX(DIAMOND!$B$9:$C$102,MATCH(E20,DIAMOND!$C$9:$C$102,0),1),IF(C20="RND",INDEX(DIAMOND!$B$9:$C$102,MATCH(E20,DIAMOND!$C$9:$C$102,0),1),IF(C20="PRI",INDEX(DIAMOND!$M$9:$N$63,MATCH(E20,DIAMOND!$N$9:$N$63,0),1),IF(C20="MRQ",INDEX(DIAMOND!$S$40:$T$58,MATCH(E20,DIAMOND!$T$40:$T$58,0),1),IF(C20="PRS",INDEX(DIAMOND!$S$9:$T$35,MATCH(E20,DIAMOND!$T$9:$T$63,0),1),0))))) -> 0 | F20: =IF(C20="RNDTRD",VLOOKUP(E20,DIAMOND!$C$9:$D$102,2,0),IF(C20="RND",VLOOKUP(E20,DIAMOND!$C$9:$D$102,2,0),IF(C20="MRQ",VLOOKUP(E20,DIAMOND!$T$40:$U$58,2,0),IF(C20="PRI",VLOOKUP(E20,DIAMOND!$N$9:$O$63,2,0),IF(C20="PRITRD",VLOOKUP(E20,DIAMOND!$N$9:$O$63,2,0),IF(C20="BUG",VLOOKUP(E20,DIAMOND!$H$9:$I$45,2,0),IF(C20="BUGTRD",VLOOKUP(E20,DIAMOND!$H$9:$I$45,2,0),IF(C20="TAPTRD",VLOOKUP(E20,DIAMOND!$H$9:$I$45,2,0),IF(C20="TAP",VLOOKUP(E20,DIAMOND!$H$9:$I$45,2,0),IF(C20="PRS",VLOOKUP(E20,DIAMOND!$T$9:$U$35,2,0),IF(C20="OVL",VLOOKUP(E20,DIAMOND!$T$64:$U$82,2,0),IF(C20="EMR",VLOOKUP(E20,DIAMOND!$N$69:$O$83,2,0),0)))))))))))) -> 0 | H20: =G20*F20 -> 0
D21: =IF(C21="RNDTRD",INDEX(DIAMOND!$B$9:$C$102,MATCH(E21,DIAMOND!$C$9:$C$102,0),1),IF(C21="RND",INDEX(DIAMOND!$B$9:$C$102,MATCH(E21,DIAMOND!$C$9:$C$102,0),1),IF(C21="PRI",INDEX(DIAMOND!$M$9:$N$63,MATCH(E21,DIAMOND!$N$9:$N$63,0),1),IF(C21="MRQ",INDEX(DIAMOND!$S$40:$T$58,MATCH(E21,DIAMOND!$T$40:$T$58,0),1),IF(C21="PRS",INDEX(DIAMOND!$S$9:$T$35,MATCH(E21,DIAMOND!$T$9:$T$63,0),1),0))))) -> 0 | F21: =IF(C21="RNDTRD",VLOOKUP(E21,DIAMOND!$C$9:$D$102,2,0),IF(C21="RND",VLOOKUP(E21,DIAMOND!$C$9:$D$102,2,0),IF(C21="MRQ",VLOOKUP(E21,DIAMOND!$T$40:$U$58,2,0),IF(C21="PRI",VLOOKUP(E21,DIAMOND!$N$9:$O$63,2,0),IF(C21="PRITRD",VLOOKUP(E21,DIAMOND!$N$9:$O$63,2,0),IF(C21="BUG",VLOOKUP(E21,DIAMOND!$H$9:$I$45,2,0),IF(C21="BUGTRD",VLOOKUP(E21,DIAMOND!$H$9:$I$45,2,0),IF(C21="TAPTRD",VLOOKUP(E21,DIAMOND!$H$9:$I$45,2,0),IF(C21="TAP",VLOOKUP(E21,DIAMOND!$H$9:$I$45,2,0),IF(C21="PRS",VLOOKUP(E21,DIAMOND!$T$9:$U$35,2,0),IF(C21="OVL",VLOOKUP(E21,DIAMOND!$T$64:$U$82,2,0),IF(C21="EMR",VLOOKUP(E21,DIAMOND!$N$69:$O$83,2,0),0)))))))))))) -> 0 | H21: =G21*F21 -> 0
D22: =IF(C22="RNDTRD",INDEX(DIAMOND!$B$9:$C$102,MATCH(E22,DIAMOND!$C$9:$C$102,0),1),IF(C22="RND",INDEX(DIAMOND!$B$9:$C$102,MATCH(E22,DIAMOND!$C$9:$C$102,0),1),IF(C22="PRI",INDEX(DIAMOND!$M$9:$N$63,MATCH(E22,DIAMOND!$N$9:$N$63,0),1),IF(C22="MRQ",INDEX(DIAMOND!$S$40:$T$58,MATCH(E22,DIAMOND!$T$40:$T$58,0),1),IF(C22="PRS",INDEX(DIAMOND!$S$9:$T$35,MATCH(E22,DIAMOND!$T$9:$T$63,0),1),0))))) -> 0 | F22: =IF(C22="RNDTRD",VLOOKUP(E22,DIAMOND!$C$9:$D$102,2,0),IF(C22="RND",VLOOKUP(E22,DIAMOND!$C$9:$D$102,2,0),IF(C22="MRQ",VLOOKUP(E22,DIAMOND!$T$40:$U$58,2,0),IF(C22="PRI",VLOOKUP(E22,DIAMOND!$N$9:$O$63,2,0),IF(C22="PRITRD",VLOOKUP(E22,DIAMOND!$N$9:$O$63,2,0),IF(C22="BUG",VLOOKUP(E22,DIAMOND!$H$9:$I$45,2,0),IF(C22="BUGTRD",VLOOKUP(E22,DIAMOND!$H$9:$I$45,2,0),IF(C22="TAPTRD",VLOOKUP(E22,DIAMOND!$H$9:$I$45,2,0),IF(C22="TAP",VLOOKUP(E22,DIAMOND!$H$9:$I$45,2,0),IF(C22="PRS",VLOOKUP(E22,DIAMOND!$T$9:$U$35,2,0),IF(C22="OVL",VLOOKUP(E22,DIAMOND!$T$64:$U$82,2,0),IF(C22="EMR",VLOOKUP(E22,DIAMOND!$N$69:$O$83,2,0),0)))))))))))) -> 0 | H22: =G22*F22 -> 0
D23: =IF(C23="RNDTRD",INDEX(DIAMOND!$B$9:$C$102,MATCH(E23,DIAMOND!$C$9:$C$102,0),1),IF(C23="RND",INDEX(DIAMOND!$B$9:$C$102,MATCH(E23,DIAMOND!$C$9:$C$102,0),1),IF(C23="PRI",INDEX(DIAMOND!$M$9:$N$63,MATCH(E23,DIAMOND!$N$9:$N$63,0),1),IF(C23="MRQ",INDEX(DIAMOND!$S$40:$T$58,MATCH(E23,DIAMOND!$T$40:$T$58,0),1),IF(C23="PRS",INDEX(DIAMOND!$S$9:$T$35,MATCH(E23,DIAMOND!$T$9:$T$63,0),1),0))))) -> 0 | F23: =IF(C23="RNDTRD",VLOOKUP(E23,DIAMOND!$C$9:$D$102,2,0),IF(C23="RND",VLOOKUP(E23,DIAMOND!$C$9:$D$102,2,0),IF(C23="MRQ",VLOOKUP(E23,DIAMOND!$T$40:$U$58,2,0),IF(C23="PRI",VLOOKUP(E23,DIAMOND!$N$9:$O$63,2,0),IF(C23="PRITRD",VLOOKUP(E23,DIAMOND!$N$9:$O$63,2,0),IF(C23="BUG",VLOOKUP(E23,DIAMOND!$H$9:$I$45,2,0),IF(C23="BUGTRD",VLOOKUP(E23,DIAMOND!$H$9:$I$45,2,0),IF(C23="TAPTRD",VLOOKUP(E23,DIAMOND!$H$9:$I$45,2,0),IF(C23="TAP",VLOOKUP(E23,DIAMOND!$H$9:$I$45,2,0),IF(C23="PRS",VLOOKUP(E23,DIAMOND!$T$9:$U$35,2,0),IF(C23="OVL",VLOOKUP(E23,DIAMOND!$T$64:$U$82,2,0),IF(C23="EMR",VLOOKUP(E23,DIAMOND!$N$69:$O$83,2,0),0)))))))))))) -> 0 | H23: =G23*F23 -> 0
D24: =IF(C24="RNDTRD",INDEX(DIAMOND!$B$9:$C$102,MATCH(E24,DIAMOND!$C$9:$C$102,0),1),IF(C24="RND",INDEX(DIAMOND!$B$9:$C$102,MATCH(E24,DIAMOND!$C$9:$C$102,0),1),IF(C24="PRI",INDEX(DIAMOND!$M$9:$N$63,MATCH(E24,DIAMOND!$N$9:$N$63,0),1),IF(C24="MRQ",INDEX(DIAMOND!$S$40:$T$58,MATCH(E24,DIAMOND!$T$40:$T$58,0),1),IF(C24="PRS",INDEX(DIAMOND!$S$9:$T$35,MATCH(E24,DIAMOND!$T$9:$T$63,0),1),0))))) -> 0 | F24: =IF(C24="RNDTRD",VLOOKUP(E24,DIAMOND!$C$9:$D$102,2,0),IF(C24="RND",VLOOKUP(E24,DIAMOND!$C$9:$D$102,2,0),IF(C24="MRQ",VLOOKUP(E24,DIAMOND!$T$40:$U$58,2,0),IF(C24="PRI",VLOOKUP(E24,DIAMOND!$N$9:$O$63,2,0),IF(C24="PRITRD",VLOOKUP(E24,DIAMOND!$N$9:$O$63,2,0),IF(C24="BUG",VLOOKUP(E24,DIAMOND!$H$9:$I$45,2,0),IF(C24="BUGTRD",VLOOKUP(E24,DIAMOND!$H$9:$I$45,2,0),IF(C24="TAPTRD",VLOOKUP(E24,DIAMOND!$H$9:$I$45,2,0),IF(C24="TAP",VLOOKUP(E24,DIAMOND!$H$9:$I$45,2,0),IF(C24="PRS",VLOOKUP(E24,DIAMOND!$T$9:$U$35,2,0),IF(C24="OVL",VLOOKUP(E24,DIAMOND!$T$64:$U$82,2,0),IF(C24="EMR",VLOOKUP(E24,DIAMOND!$N$69:$O$83,2,0),0)))))))))))) -> 0 | H24: =G24*F24 -> 0
D25: =IF(C25="RNDTRD",INDEX(DIAMOND!$B$9:$C$102,MATCH(E25,DIAMOND!$C$9:$C$102,0),1),IF(C25="RND",INDEX(DIAMOND!$B$9:$C$102,MATCH(E25,DIAMOND!$C$9:$C$102,0),1),IF(C25="PRI",INDEX(DIAMOND!$M$9:$N$63,MATCH(E25,DIAMOND!$N$9:$N$63,0),1),IF(C25="MRQ",INDEX(DIAMOND!$S$40:$T$58,MATCH(E25,DIAMOND!$T$40:$T$58,0),1),IF(C25="PRS",INDEX(DIAMOND!$S$9:$T$35,MATCH(E25,DIAMOND!$T$9:$T$63,0),1),0))))) -> 0 | F25: =IF(C25="RNDTRD",VLOOKUP(E25,DIAMOND!$C$9:$D$102,2,0),IF(C25="RND",VLOOKUP(E25,DIAMOND!$C$9:$D$102,2,0),IF(C25="MRQ",VLOOKUP(E25,DIAMOND!$T$40:$U$58,2,0),IF(C25="PRI",VLOOKUP(E25,DIAMOND!$N$9:$O$63,2,0),IF(C25="PRITRD",VLOOKUP(E25,DIAMOND!$N$9:$O$63,2,0),IF(C25="BUG",VLOOKUP(E25,DIAMOND!$H$9:$I$45,2,0),IF(C25="BUGTRD",VLOOKUP(E25,DIAMOND!$H$9:$I$45,2,0),IF(C25="TAPTRD",VLOOKUP(E25,DIAMOND!$H$9:$I$45,2,0),IF(C25="TAP",VLOOKUP(E25,DIAMOND!$H$9:$I$45,2,0),IF(C25="PRS",VLOOKUP(E25,DIAMOND!$T$9:$U$35,2,0),IF(C25="OVL",VLOOKUP(E25,DIAMOND!$T$64:$U$82,2,0),IF(C25="EMR",VLOOKUP(E25,DIAMOND!$N$69:$O$83,2,0),0)))))))))))) -> 0 | H25: =G25*F25 -> 0
D26: =IF(C26="RNDTRD",INDEX(DIAMOND!$B$9:$C$102,MATCH(E26,DIAMOND!$C$9:$C$102,0),1),IF(C26="RND",INDEX(DIAMOND!$B$9:$C$102,MATCH(E26,DIAMOND!$C$9:$C$102,0),1),IF(C26="PRI",INDEX(DIAMOND!$M$9:$N$63,MATCH(E26,DIAMOND!$N$9:$N$63,0),1),IF(C26="MRQ",INDEX(DIAMOND!$S$40:$T$58,MATCH(E26,DIAMOND!$T$40:$T$58,0),1),IF(C26="PRS",INDEX(DIAMOND!$S$9:$T$35,MATCH(E26,DIAMOND!$T$9:$T$63,0),1),0))))) -> 0 | F26: =IF(C26="RNDTRD",VLOOKUP(E26,DIAMOND!$C$9:$D$102,2,0),IF(C26="RND",VLOOKUP(E26,DIAMOND!$C$9:$D$102,2,0),IF(C26="MRQ",VLOOKUP(E26,DIAMOND!$T$40:$U$58,2,0),IF(C26="PRI",VLOOKUP(E26,DIAMOND!$N$9:$O$63,2,0),IF(C26="PRITRD",VLOOKUP(E26,DIAMOND!$N$9:$O$63,2,0),IF(C26="BUG",VLOOKUP(E26,DIAMOND!$H$9:$I$45,2,0),IF(C26="BUGTRD",VLOOKUP(E26,DIAMOND!$H$9:$I$45,2,0),IF(C26="TAPTRD",VLOOKUP(E26,DIAMOND!$H$9:$I$45,2,0),IF(C26="TAP",VLOOKUP(E26,DIAMOND!$H$9:$I$45,2,0),IF(C26="PRS",VLOOKUP(E26,DIAMOND!$T$9:$U$35,2,0),IF(C26="OVL",VLOOKUP(E26,DIAMOND!$T$64:$U$82,2,0),IF(C26="EMR",VLOOKUP(E26,DIAMOND!$N$69:$O$83,2,0),0)))))))))))) -> 0 | H26: =G26*F26 -> 0
D27: =IF(C27="RNDTRD",INDEX(DIAMOND!$B$9:$C$102,MATCH(E27,DIAMOND!$C$9:$C$102,0),1),IF(C27="RND",INDEX(DIAMOND!$B$9:$C$102,MATCH(E27,DIAMOND!$C$9:$C$102,0),1),IF(C27="PRI",INDEX(DIAMOND!$M$9:$N$63,MATCH(E27,DIAMOND!$N$9:$N$63,0),1),IF(C27="MRQ",INDEX(DIAMOND!$S$40:$T$58,MATCH(E27,DIAMOND!$T$40:$T$58,0),1),IF(C27="PRS",INDEX(DIAMOND!$S$9:$T$35,MATCH(E27,DIAMOND!$T$9:$T$63,0),1),0))))) -> 0 | F27: =IF(C27="RNDTRD",VLOOKUP(E27,DIAMOND!$C$9:$D$102,2,0),IF(C27="RND",VLOOKUP(E27,DIAMOND!$C$9:$D$102,2,0),IF(C27="MRQ",VLOOKUP(E27,DIAMOND!$T$40:$U$58,2,0),IF(C27="PRI",VLOOKUP(E27,DIAMOND!$N$9:$O$63,2,0),IF(C27="PRITRD",VLOOKUP(E27,DIAMOND!$N$9:$O$63,2,0),IF(C27="BUG",VLOOKUP(E27,DIAMOND!$H$9:$I$45,2,0),IF(C27="BUGTRD",VLOOKUP(E27,DIAMOND!$H$9:$I$45,2,0),IF(C27="TAPTRD",VLOOKUP(E27,DIAMOND!$H$9:$I$45,2,0),IF(C27="TAP",VLOOKUP(E27,DIAMOND!$H$9:$I$45,2,0),IF(C27="PRS",VLOOKUP(E27,DIAMOND!$T$9:$U$35,2,0),IF(C27="OVL",VLOOKUP(E27,DIAMOND!$T$64:$U$82,2,0),IF(C27="EMR",VLOOKUP(E27,DIAMOND!$N$69:$O$83,2,0),0)))))))))))) -> 0 | H27: =G27*F27 -> 0
D28: =IF(C28="RNDTRD",INDEX(DIAMOND!$B$9:$C$102,MATCH(E28,DIAMOND!$C$9:$C$102,0),1),IF(C28="RND",INDEX(DIAMOND!$B$9:$C$102,MATCH(E28,DIAMOND!$C$9:$C$102,0),1),IF(C28="PRI",INDEX(DIAMOND!$M$9:$N$63,MATCH(E28,DIAMOND!$N$9:$N$63,0),1),IF(C28="MRQ",INDEX(DIAMOND!$S$40:$T$58,MATCH(E28,DIAMOND!$T$40:$T$58,0),1),IF(C28="PRS",INDEX(DIAMOND!$S$9:$T$35,MATCH(E28,DIAMOND!$T$9:$T$63,0),1),0))))) -> 0 | F28: =IF(C28="RNDTRD",VLOOKUP(E28,DIAMOND!$C$9:$D$102,2,0),IF(C28="RND",VLOOKUP(E28,DIAMOND!$C$9:$D$102,2,0),IF(C28="MRQ",VLOOKUP(E28,DIAMOND!$T$40:$U$58,2,0),IF(C28="PRI",VLOOKUP(E28,DIAMOND!$N$9:$O$63,2,0),IF(C28="PRITRD",VLOOKUP(E28,DIAMOND!$N$9:$O$63,2,0),IF(C28="BUG",VLOOKUP(E28,DIAMOND!$H$9:$I$45,2,0),IF(C28="BUGTRD",VLOOKUP(E28,DIAMOND!$H$9:$I$45,2,0),IF(C28="TAPTRD",VLOOKUP(E28,DIAMOND!$H$9:$I$45,2,0),IF(C28="TAP",VLOOKUP(E28,DIAMOND!$H$9:$I$45,2,0),IF(C28="PRS",VLOOKUP(E28,DIAMOND!$T$9:$U$35,2,0),IF(C28="OVL",VLOOKUP(E28,DIAMOND!$T$64:$U$82,2,0),IF(C28="EMR",VLOOKUP(E28,DIAMOND!$N$69:$O$83,2,0),0)))))))))))) -> 0 | H28: =G28*F28 -> 0
D29: =IF(C29="RNDTRD",INDEX(DIAMOND!$B$9:$C$102,MATCH(E29,DIAMOND!$C$9:$C$102,0),1),IF(C29="RND",INDEX(DIAMOND!$B$9:$C$102,MATCH(E29,DIAMOND!$C$9:$C$102,0),1),IF(C29="PRI",INDEX(DIAMOND!$M$9:$N$63,MATCH(E29,DIAMOND!$N$9:$N$63,0),1),IF(C29="MRQ",INDEX(DIAMOND!$S$40:$T$58,MATCH(E29,DIAMOND!$T$40:$T$58,0),1),IF(C29="PRS",INDEX(DIAMOND!$S$9:$T$35,MATCH(E29,DIAMOND!$T$9:$T$63,0),1),0))))) -> 0 | F29: =IF(C29="RNDTRD",VLOOKUP(E29,DIAMOND!$C$9:$D$102,2,0),IF(C29="RND",VLOOKUP(E29,DIAMOND!$C$9:$D$102,2,0),IF(C29="MRQ",VLOOKUP(E29,DIAMOND!$T$40:$U$58,2,0),IF(C29="PRI",VLOOKUP(E29,DIAMOND!$N$9:$O$63,2,0),IF(C29="PRITRD",VLOOKUP(E29,DIAMOND!$N$9:$O$63,2,0),IF(C29="BUG",VLOOKUP(E29,DIAMOND!$H$9:$I$45,2,0),IF(C29="BUGTRD",VLOOKUP(E29,DIAMOND!$H$9:$I$45,2,0),IF(C29="TAPTRD",VLOOKUP(E29,DIAMOND!$H$9:$I$45,2,0),IF(C29="TAP",VLOOKUP(E29,DIAMOND!$H$9:$I$45,2,0),IF(C29="PRS",VLOOKUP(E29,DIAMOND!$T$9:$U$35,2,0),IF(C29="OVL",VLOOKUP(E29,DIAMOND!$T$64:$U$82,2,0),IF(C29="EMR",VLOOKUP(E29,DIAMOND!$N$69:$O$83,2,0),0)))))))))))) -> 0 | H29: =G29*F29 -> 0
D30: =IF(C30="RNDTRD",INDEX(DIAMOND!$B$9:$C$102,MATCH(E30,DIAMOND!$C$9:$C$102,0),1),IF(C30="RND",INDEX(DIAMOND!$B$9:$C$102,MATCH(E30,DIAMOND!$C$9:$C$102,0),1),IF(C30="PRI",INDEX(DIAMOND!$M$9:$N$63,MATCH(E30,DIAMOND!$N$9:$N$63,0),1),IF(C30="MRQ",INDEX(DIAMOND!$S$40:$T$58,MATCH(E30,DIAMOND!$T$40:$T$58,0),1),IF(C30="PRS",INDEX(DIAMOND!$S$9:$T$35,MATCH(E30,DIAMOND!$T$9:$T$63,0),1),0))))) -> 0 | F30: =IF(C30="RNDTRD",VLOOKUP(E30,DIAMOND!$C$9:$D$102,2,0),IF(C30="RND",VLOOKUP(E30,DIAMOND!$C$9:$D$102,2,0),IF(C30="MRQ",VLOOKUP(E30,DIAMOND!$T$40:$U$58,2,0),IF(C30="PRI",VLOOKUP(E30,DIAMOND!$N$9:$O$63,2,0),IF(C30="PRITRD",VLOOKUP(E30,DIAMOND!$N$9:$O$63,2,0),IF(C30="BUG",VLOOKUP(E30,DIAMOND!$H$9:$I$45,2,0),IF(C30="BUGTRD",VLOOKUP(E30,DIAMOND!$H$9:$I$45,2,0),IF(C30="TAPTRD",VLOOKUP(E30,DIAMOND!$H$9:$I$45,2,0),IF(C30="TAP",VLOOKUP(E30,DIAMOND!$H$9:$I$45,2,0),IF(C30="PRS",VLOOKUP(E30,DIAMOND!$T$9:$U$35,2,0),IF(C30="OVL",VLOOKUP(E30,DIAMOND!$T$64:$U$82,2,0),IF(C30="EMR",VLOOKUP(E30,DIAMOND!$N$69:$O$83,2,0),0)))))))))))) -> 0 | H30: =G30*F30 -> 0
D31: =IF(C31="RNDTRD",INDEX(DIAMOND!$B$9:$C$102,MATCH(E31,DIAMOND!$C$9:$C$102,0),1),IF(C31="RND",INDEX(DIAMOND!$B$9:$C$102,MATCH(E31,DIAMOND!$C$9:$C$102,0),1),IF(C31="PRI",INDEX(DIAMOND!$M$9:$N$63,MATCH(E31,DIAMOND!$N$9:$N$63,0),1),IF(C31="MRQ",INDEX(DIAMOND!$S$40:$T$58,MATCH(E31,DIAMOND!$T$40:$T$58,0),1),IF(C31="PRS",INDEX(DIAMOND!$S$9:$T$35,MATCH(E31,DIAMOND!$T$9:$T$63,0),1),0))))) -> 0 | F31: =IF(C31="RNDTRD",VLOOKUP(E31,DIAMOND!$C$9:$D$102,2,0),IF(C31="RND",VLOOKUP(E31,DIAMOND!$C$9:$D$102,2,0),IF(C31="MRQ",VLOOKUP(E31,DIAMOND!$T$40:$U$58,2,0),IF(C31="PRI",VLOOKUP(E31,DIAMOND!$N$9:$O$63,2,0),IF(C31="PRITRD",VLOOKUP(E31,DIAMOND!$N$9:$O$63,2,0),IF(C31="BUG",VLOOKUP(E31,DIAMOND!$H$9:$I$45,2,0),IF(C31="BUGTRD",VLOOKUP(E31,DIAMOND!$H$9:$I$45,2,0),IF(C31="TAPTRD",VLOOKUP(E31,DIAMOND!$H$9:$I$45,2,0),IF(C31="TAP",VLOOKUP(E31,DIAMOND!$H$9:$I$45,2,0),IF(C31="PRS",VLOOKUP(E31,DIAMOND!$T$9:$U$35,2,0),IF(C31="OVL",VLOOKUP(E31,DIAMOND!$T$64:$U$82,2,0),IF(C31="EMR",VLOOKUP(E31,DIAMOND!$N$69:$O$83,2,0),0)))))))))))) -> 0 | H31: =G31*F31 -> 0
... D38: =IF(C38="RNDTRD",INDEX(DIAMOND!$B$9:$C$102,MATCH(E38,DIAMOND!$C$9:$C$102,0),1),IF(C38="RND",INDEX(DIAMOND!$B$9:$C$102,MATCH(E38,DIAMOND!$C$9:$C$102,0),1),IF(C38="PRI",INDEX(DIAMOND!$M$9:$N$63,MATCH(E38,DIAMOND!$N$9:$N$63,0),1),IF(C38="MRQ",INDEX(DIAMOND!$S$40:$T$58,MATCH(E38,DIAMOND!$T$40:$T$58,0),1),IF(C38="PRS",INDEX(DIAMOND!$S$9:$T$35,MATCH(E38,DIAMOND!$T$9:$T$63,0),1),0))))) -> 0 | F38: =IF(C38="RNDTRD",VLOOKUP(E38,DIAMOND!$C$9:$D$102,2,0),IF(C38="RND",VLOOKUP(E38,DIAMOND!$C$9:$D$102,2,0),IF(C38="MRQ",VLOOKUP(E38,DIAMOND!$T$40:$U$58,2,0),IF(C38="PRI",VLOOKUP(E38,DIAMOND!$N$9:$O$63,2,0),IF(C38="PRITRD",VLOOKUP(E38,DIAMOND!$N$9:$O$63,2,0),IF(C38="BUG",VLOOKUP(E38,DIAMOND!$H$9:$I$45,2,0),IF(C38="BUGTRD",VLOOKUP(E38,DIAMOND!$H$9:$I$45,2,0),IF(C38="TAPTRD",VLOOKUP(E38,DIAMOND!$H$9:$I$45,2,0),IF(C38="TAP",VLOOKUP(E38,DIAMOND!$H$9:$I$45,2,0),IF(C38="PRS",VLOOKUP(E38,DIAMOND!$T$9:$U$35,2,0),IF(C38="OVL",VLOOKUP(E38,DIAMOND!$T$64:$U$82,2,0),IF(C38="EMR",VLOOKUP(E38,DIAMOND!$N$69:$O$83,2,0),0)))))))))))) -> 0 | H38: =G38*F38 -> 0
C39: Total | G39: =SUMIF(G9:G38,">0",G9:G38) -> 31 | H39: =SUMIF(H9:H38,">0",H9:H38) -> 1.42

Sheet DIAMOND
B2: CREATED BY : | E2: DIAMOND CHART
B3: MEZZARIA JEWELS
C4: PCS | F4: WT.
C5: =SUM(J64) -> 0 | D5: TOTAL | F5: =K64 -> 0
B6: ROUND | H6: Taper-Bugget | M6: PRINCESS | S6: PEAR
B8: SIEVE SIZE | C8: M.M. SIZE | D8: WEIGHT | E8: QTY. | F8: TOTAL | H8: M.M. SIZE | I8: WEIGHT | J8: QTY. | K8: TOTAL | M8: SIEVE SIZE | N8: M.M. SIZE | O8: WEIGHT | P8: QTY. | Q8: TOTAL | S8: SIZE | T8: M.M. SIZE | U8: WEIGHT | V8: QTY. | W8: TOTAL
B9: +0000-000 | C9: 0.8 | D9: 0.003 | F9: =E9*D9 -> 0 | H9: 1 | I9: 0.003 | K9: =J9*I9 -> 0 | M9: *** | N9: 0.9 | O9: 0.005 | Q9: =P9*O9 -> 0 | S9: *** | T9: 3x2 | U9: 0.05 | W9: =U9*V9 -> 0
B10: +000-00 | C10: 0.9 | D10: 0.004 | F10: =E10*D10 -> 0 | H10: 1.1 | I10: 0.004 | K10: =J10*I10 -> 0 | M10: *** | N10: 1 | O10: 0.0062 | Q10: =P10*O10 -> 0 | S10: *** | T10: 3.3x2.2 | U10: 0.07 | W10: =U10*V10 -> 0
B11: +00-0.5 | C11: 1 | D11: 0.005 | F11: =E11*D11 -> 0 | H11: 1.2 | I11: 0.005 | K11: =J11*I11 -> 0 | M11: *** | N11: 1.1 | O11: 0.008 | Q11: =P11*O11 -> 0 | S11: *** | T11: 3.5x2.3 | U11: 0.08 | W11: =U11*V11 -> 0
B12: +0.5-1.0 | C12: 1.1 | D12: 0.006 | F12: =E12*D12 -> 0 | H12: 1.3 | I12: 0.006 | K12: =J12*I12 -> 0 | M12: *** | N12: 1.15 | O12: 0.009 | Q12: =P12*O12 -> 0 | S12: *** | T12: 3.8x2.5 | U12: 0.09 | W12: =U12*V12 -> 0
B13: +1.0-1.5 | C13: 1.15 | D13: 0.007 | F13: =E13*D13 -> 0 | H13: 1.4 | I13: 0.007 | K13: =J13*I13 -> 0 | M13: *** | N13: 1.2 | O13: 0.01 | Q13: =P13*O13 -> 0 | S13: *** | T13: 4x2.5 | U13: 0.14 | W13: =U13*V13 -> 0
B14: +1.5-2.0 | C14: 1.2 | D14: 0.008 | F14: =E14*D14 -> 0 | H14: 1.5 | I14: 0.008 | K14: =J14*I14 -> 0 | M14: *** | N14: 1.25 | O14: 0.012 | Q14: =P14*O14 -> 0 | S14: *** | T14: 4.3x2.7 | U14: 0.15 | W14: =U14*V14 -> 0
B15: +2.0-2.5 | C15: 1.25 | D15: 0.009 | F15: =E15*D15 -> 0 | H15: 1.6X.8 | I15: 0.009 | K15: =J15*I15 -> 0 | M15: *** | N15: 1.3 | O15: 0.017 | Q15: =P15*O15 -> 0 | S15: *** | T15: 4.7x3.2 | U15: 0.2 | W15: =U15*V15 -> 0
B16: +2.5-3.0 | C16: 1.3 | D16: 0.01 | F16: =E16*D16 -> 0 | H16: 1.7X.9 | I16: 0.01 | K16: =J16*I16 -> 0 | M16: *** | N16: 1.35 | O16: 0.018 | Q16: =P16*O16 -> 0 | S16: *** | T16: 4.8x3.3 | U16: 0.23 | W16: =U16*V16 -> 0
B17: +3.0-3.5 | C17: 1.35 | D17: 0.011 | F17: =E17*D17 -> 0 | H17: 1.8X.9 | I17: 0.012 | K17: =J17*I17 -> 0 | M17: *** | N17: 1.4 | O17: 0.019 | Q17: =P17*O17 -> 0 | S17: *** | T17: 5x3.5 | U17: 0.25 | W17: =U17*V17 -> 0
B18: +3.5-4.0 | C18: 1.4 | D18: 0.012 | F18: =E18*D18 -> 0 | H18: 1.9X1 | I18: 0.014 | K18: =J18*I18 -> 0 | M18: *** | N18: 1.45 | O18: 0.02 | Q18: =P18*O18 -> 0 | S18: *** | T18: 5.1x3.7 | U18: 0.3 | W18: =U18*V18 -> 0
B19: +4.0-4.5 | C19: 1.45 | D19: 0.014 | F19: =E19*D19 -> 0 | H19: 2X1 | I19: 0.016 | K19: =J19*I19 -> 0 | M19: *** | N19: 1.5 | O19: 0.025 | Q19: =P19*O19 -> 0 | S19: *** | T19: 5.3x4 | U19: 0.33 | W19: =U19*V19 -> 0
B20: +4.5-5.0 | C20: 1.5 | D20: 0.015 | F20: =E20*D20 -> 0 | H20: 2.1X1 | I20: 0.019 | K20: =J20*I20 -> 0 | M20: *** | N20: 1.55 | O20: 0.023 | Q20: =P20*O20 -> 0 | S20: *** | T20: 5.4x4.2 | U20: 0.4 | W20: =U20*V20 -> 0
B21: +5.0-5.5 | C21: 1.55 | D21: 0.016 | F21: =E21*D21 -> 0 | H21: 2.2X1.1 | I21: 0.02 | K21: =J21*I21 -> 0 | M21: *** | N21: 1.6 | O21: 0.03 | Q21: =P21*O21 -> 0 | S21: *** | T21: 5.6x4.3 | U21: 0.45 | W21: =U21*V21 -> 0
B22: +5.5-6.0 | C22: 1.6 | D22: 0.018 | F22: =E22*D22 -> 0 | H22: 2.3X1.1 | I22: 0.021 | K22: =J22*I22 -> 0 | M22: *** | N22: 1.7 | O22: 0.035 | Q22: =P22*O22 -> 0 | S22: *** | T22: 6.6X4.3 | U22: 0.5 | W22: =U22*V22 -> 0
B23: +6.0-6.5 | C23: 1.7 | D23: 0.02 | F23: =E23*D23 -> 0 | H23: 2.4 | I23: 0.023 | K23: =J23*I23 -> 0 | M23: *** | N23: 1.8 | O23: 0.04 | Q23: =P23*O23 -> 0 | S23: *** | T23: 5.8x4.5 | U23: 0.6 | W23: =U23*V23 -> 0
B24: MELE | H24: 2.5 | I24: 0.025 | K24: =J24*I24 -> 0 | M24: *** | N24: 1.9 | O24: 0.045 | Q24: =P24*O24 -> 0 | S24: *** | T24: 7.5X4.9 | U24: 0.7 | W24: =U24*V24 -> 0
B25: +6.5-7.0 | C25: 1.8 | D25: 0.025 | F25: =E25*D25 -> 0 | H25: 2.6 | I25: 0.029 | K25: =J25*I25 -> 0 | M25: *** | N25: 2 | O25: 0.05 | Q25: =P25*O25 -> 0 | S25: *** | T25: 5.1X3.7 | U25: 0.3 | W25: =U25*V25 -> 0
B26: +7.0-7.5 | C26: 1.9 | D26: 0.03 | F26: =E26*D26 -> 0 | H26: 2.7 | I26: 0.032 | K26: =J26*I26 -> 0 | M26: *** | N26: 2.1 | O26: 0.06 | Q26: =P26*O26 -> 0 | S26: *** | T26: 6.6X4.3 | U26: 0.5 | W26: =U26*V26 -> 0
B27: +7.5-8.0 | C27: 2 | D27: 0.035 | F27: =E27*D27 -> 0 | H27: 2.8 | I27: 0.035 | K27: =J27*I27 -> 0 | M27: *** | N27: 2.2 | O27: 0.07 | Q27: =P27*O27 -> 0 | S27: *** | T27: 7.5X4.9 | U27: 0.7 | W27: =U27*V27 -> 0
B28: +8.0-8.5 | C28: 2.1 | D28: 0.04 | F28: =E28*D28 -> 0 | H28: 2.9 | I28: 0.038 | K28: =J28*I28 -> 0 | M28: *** | N28: 2.3 | O28: 0.08 | Q28: =P28*O28 -> 0 | S28: *** | T28: 8.4X5.6 | U28: 1 | W28: =U28*V28 -> 0
B29: +8.5-9.0 | C29: 2.2 | D29: 0.045 | F29: =E29*D29 -> 0 | H29: 3 | I29: 0.041 | K29: =J29*I29 -> 0 | M29: *** | N29: 2.4 | O29: 0.09 | Q29: =P29*O29 -> 0 | S29: *** | T29: 9.7X6.3 | U29: 1.5 | W29: =U29*V29 -> 0
B30: +9.0-9.5 | C30: 2.3 | D30: 0.05 | F30: =E30*D30 -> 0 | H30: 3.1 | I30: 0.045 | K30: =J30*I30 -> 0 | M30: *** | N30: 2.5 | O30: 0.1 | Q30: =P30*O30 -> 0 | S30: *** | T30: 10x7 | U30: 2 | W30: =U30*V30 -> 0
B31: +9.5-10.0 | C31: 2.4 | D31: 0.06 | F31: =E31*D31 -> 0 | H31: 3.2 | I31: 0.05 | K31: =J31*I31 -> 0 | M31: *** | N31: 2.6 | O31: 0.11 | Q31: =P31*O31 -> 0 | S31: *** | T31: 11x7 | U31: 2.25 | W31: =U31*V31 -> 0
B32: +10.0-10.5 | C32: 2.5 | D32: 0.065 | F32: =E32*D32 -> 0 | H32: 3.3 | I32: 0.052 | K32: =J32*I32 -> 0 | M32: *** | N32: 2.7 | O32: 0.123 | Q32: =P32*O32 -> 0 | S32: *** | T32: 12x8 | U32: 3 | W32: =U32*V32 -> 0
B33: +10.5-11.0 | C33: 2.6 | D33: 0.07 | F33: =E33*D33 -> 0 | H33: 3.4 | I33: 0.066 | K33: =J33*I33 -> 0 | M33: *** | N33: 2.8 | O33: 0.137 | Q33: =P33*O33 -> 0 | S33: *** | T33: 13x9 | U33: 3.5 | W33: =U33*V33 -> 0
B34: +11.0-11.5 | C34: 2.7 | D34: 0.08 | F34: =E34*D34 -> 0 | H34: 3.5 | I34: 0.076 | K34: =J34*I34 -> 0 | M34: *** | N34: 2.9 | O34: 0.15 | Q34: =P34*O34 -> 0 | S34: *** | T34: 15x10 | U34: 5.5 | W34: =U34*V34 -> 0
B35: +11.5-12.0 | C35: 2.8 | D35: 0.09 | F35: =E35*D35 -> 0 | H35: 3.6 | I35: 0.08 | K35: =J35*I35 -> 0 | M35: *** | N35: 3 | O35: 0.169 | Q35: =P35*O35 -> 0 | S35: *** | T35: 16x12 | U35: 8.6 | W35: =U35*V35 -> 0
B36: +12.0-12.5 | C36: 2.9 | D36: 0.1 | F36: =E36*D36 -> 0 | H36: 3.7 | I36: 0.084 | K36: =J36*I36 -> 0 | M36: *** | N36: 3.1 | O36: 0.186 | Q36: =P36*O36 -> 0 | S36: PEAR | V36: =SUM(V9:V35) -> 0 | W36: =SUM(W9:W35) -> 0
B37: +12.5-13.0 | C37: 3 | D37: 0.11 | F37: =E37*D37 -> 0 | H37: 1.9X.9X.7 | I37: 0.009 | K37: =J37*I37 -> 0 | M37: *** | N37: 3.2 | O37: 0.2 | Q37: =P37*O37 -> 0
B38: +13.0-13.5 | C38: 3.1 | D38: 0.12 | F38: =E38*D38 -> 0 | H38: 1.7X1X.8 | I38: 0.01 | K38: =J38*I38 -> 0 | M38: *** | N38: 3.3 | O38: 0.224 | Q38: =P38*O38 -> 0 | S38: MARQUIES
B39: +13.5-14.0 | C39: 3.2 | D39: 0.13 | F39: =E39*D39 -> 0 | H39: 1.8X1X.8 | I39: 0.012 | K39: =J39*I39 -> 0 | M39: *** | N39: 3.4 | O39: 0.25 | Q39: =P39*O39 -> 0 | S39: SIZE | T39: M.M. SIZE | U39: WEIGHT | V39: QTY. | W39: TOTAL
B40: +14.0-14.5 | C40: 3.3 | D40: 0.146 | F40: =E40*D40 -> 0 | H40: 1.9X1.1X.9 | I40: 0.014 | K40: =J40*I40 -> 0 | M40: *** | N40: 3.5 | O40: 0.268 | Q40: =P40*O40 -> 0 | S40: *** | T40: 3x1.5 | U40: 0.03 | W40: =U40*V40 -> 0
B41: +14.5-15.0 | C41: 3.4 | D41: 0.153 | F41: =E41*D41 -> 0 | H41: 2X1.1X.9 | I41: 0.016 | K41: =J41*I41 -> 0 | M41: *** | N41: 3.6 | O41: 0.291 | Q41: =P41*O41 -> 0 | S41: *** | T41: 3.3x1.7 | U41: 0.045 | W41: =U41*V41 -> 0
B42: +15.0-15.5 | C42: 3.5 | D42: 0.165 | F42: =E42*D42 -> 0 | H42: 2.1X1.1X.9 | I42: 0.019 | K42: =J42*I42 -> 0 | M42: *** | N42: 3.7 | O42: 0.3 | Q42: =P42*O42 -> 0 | S42: *** | T42: 3.5x1.7 | U42: 0.055 | W42: =U42*V42 -> 0
...

Sheet Diamond Back
B2: CREATED BY : | E2: DIAMOND CHART
B3: KALISTA JEWELS
C4: PCS | F4: WT.
C5: =SUM(J64) -> 0 | D5: TOTAL | F5: =K64 -> 0
B6: ROUND | H6: TAPER | M6: PRINCESS | S6: PEAR
B8: SIEVE SIZE | C8: M.M. SIZE | D8: WEIGHT | E8: QTY. | F8: TOTAL | H8: M.M. SIZE | I8: WEIGHT | J8: QTY. | K8: TOTAL | M8: SIEVE SIZE | N8: M.M. SIZE | O8: WEIGHT | P8: QTY. | Q8: TOTAL | S8: SIZE | T8: M.M. SIZE | U8: WEIGHT | V8: QTY. | W8: TOTAL
B9: +0000 | C9: 0.8 | D9: 0.003 | F9: =E9*D9 -> 0 | H9: 1 | I9: 0.003 | K9: =J9*I9 -> 0 | M9: **** | N9: 0.9 | O9: 0.005 | Q9: =P9*O9 -> 0 | S9: -7 | T9: 3x2 | U9: 0.05 | W9: =U9*V9 -> 0
B10: +000 | C10: 0.9 | D10: 0.004 | F10: =E10*D10 -> 0 | H10: 1.1 | I10: 0.004 | K10: =J10*I10 -> 0 | M10: 00-0 | N10: 1 | O10: 0.0062 | Q10: =P10*O10 -> 0 | S10: -7 | T10: 3.3x2.2 | U10: 0.07 | W10: =U10*V10 -> 0
B11: +00 | C11: 1 | D11: 0.005 | F11: =E11*D11 -> 0 | H11: 1.2 | I11: 0.005 | K11: =J11*I11 -> 0 | M11: 0-1 | N11: 1.1 | O11: 0.008 | Q11: =P11*O11 -> 0 | S11: +7 | T11: 3.5x2.3 | U11: 0.08 | W11: =U11*V11 -> 0
B12: +0.5 | C12: 1.1 | D12: 0.006 | F12: =E12*D12 -> 0 | H12: 1.3 | I12: 0.006 | K12: =J12*I12 -> 0 | M12: 1--1.5 | N12: 1.15 | O12: 0.009 | Q12: =P12*O12 -> 0 | S12: +7 | T12: 3.8x2.5 | U12: 0.09 | W12: =U12*V12 -> 0
B13: +1.0 | C13: 1.15 | D13: 0.007 | F13: =E13*D13 -> 0 | H13: 1.4 | I13: 0.007 | K13: =J13*I13 -> 0 | M13: 1.5--2 | N13: 1.2 | O13: 0.01 | Q13: =P13*O13 -> 0 | S13: +13-18 | T13: 4x2.5 | U13: 0.14 | W13: =U13*V13 -> 0
B14: +1.5 | C14: 1.2 | D14: 0.008 | F14: =E14*D14 -> 0 | H14: 1.5 | I14: 0.008 | K14: =J14*I14 -> 0 | M14: 2--2.5 | N14: 1.25 | O14: 0.012 | Q14: =P14*O14 -> 0 | S14: +13-18 | T14: 4.3x2.7 | U14: 0.15 | W14: =U14*V14 -> 0
B15: +2.0 | C15: 1.25 | D15: 0.009 | F15: =E15*D15 -> 0 | H15: 1.6 | I15: 0.009 | K15: =J15*I15 -> 0 | M15: 2.5--3 | N15: 1.3 | O15: 0.017 | Q15: =P15*O15 -> 0 | S15: +18-22.5 | T15: 4.7x3.2 | U15: 0.2 | W15: =U15*V15 -> 0
B16: +2.5 | C16: 1.3 | D16: 0.01 | F16: =E16*D16 -> 0 | H16: 1.7 | I16: 0.01 | K16: =J16*I16 -> 0 | M16: 3--3.5 | N16: 1.35 | O16: 0.018 | Q16: =P16*O16 -> 0 | S16: +18-22.5 | T16: 4.8x3.3 | U16: 0.23 | W16: =U16*V16 -> 0
B17: +3.0 | C17: 1.35 | D17: 0.011 | F17: =E17*D17 -> 0 | H17: 1.8 | I17: 0.012 | K17: =J17*I17 -> 0 | M17: 3.5--4 | N17: 1.4 | O17: 0.019 | Q17: =P17*O17 -> 0 | S17: +18-22.5 | T17: 5x3.5 | U17: 0.25 | W17: =U17*V17 -> 0
B18: +3.5 | C18: 1.4 | D18: 0.012 | F18: =E18*D18 -> 0 | H18: 1.9 | I18: 0.014 | K18: =J18*I18 -> 0 | M18: 4--4.5 | N18: 1.45 | O18: 0.02 | Q18: =P18*O18 -> 0 | S18: +22.5-30 | T18: 5.1x3.7 | U18: 0.3 | W18: =U18*V18 -> 0
B19: +4.0 | C19: 1.45 | D19: 0.014 | F19: =E19*D19 -> 0 | H19: 2 | I19: 0.016 | K19: =J19*I19 -> 0 | M19: 4.5--5 | N19: 1.5 | O19: 0.025 | Q19: =P19*O19 -> 0 | S19: +22.5-30 | T19: 5.3x4 | U19: 0.33 | W19: =U19*V19 -> 0
B20: +4.5 | C20: 1.5 | D20: 0.015 | F20: =E20*D20 -> 0 | H20: 2.1 | I20: 0.019 | K20: =J20*I20 -> 0 | M20: 5--5.5 | N20: 1.55 | O20: 0.023 | Q20: =P20*O20 -> 0 | S20: +22.5-30 | T20: 5.4x4.2 | U20: 0.4 | W20: =U20*V20 -> 0
B21: +5.0 | C21: 1.55 | D21: 0.016 | F21: =E21*D21 -> 0 | H21: 2.2 | I21: 0.02 | K21: =J21*I21 -> 0 | M21: 5.5--6 | N21: 1.6 | O21: 0.03 | Q21: =P21*O21 -> 0 | S21: +30-38 | T21: 5.6x4.3 | U21: 0.45 | W21: =U21*V21 -> 0
B22: +5.5 | C22: 1.6 | D22: 0.018 | F22: =E22*D22 -> 0 | H22: 2.3 | I22: 0.021 | K22: =J22*I22 -> 0 | M22: 6--6.5 | N22: 1.7 | O22: 0.035 | Q22: =P22*O22 -> 0 | S22: +30-38 | T22: 5.7x4.5 | U22: 0.5 | W22: =U22*V22 -> 0
B23: +6.0 | C23: 1.7 | D23: 0.02 | F23: =E23*D23 -> 0 | H23: 2.4 | I23: 0.023 | K23: =J23*I23 -> 0 | M23: 6.5--7 | N23: 1.8 | O23: 0.04 | Q23: =P23*O23 -> 0 | S23: +38-45 | T23: 5.8x4.5 | U23: 0.6 | W23: =U23*V23 -> 0
B24: MELE | H24: 2.5 | I24: 0.025 | K24: =J24*I24 -> 0 | M24: 7--7.5 | N24: 1.9 | O24: 0.045 | Q24: =P24*O24 -> 0 | S24: +38-45 | T24: 6x4.5 | U24: 0.7 | W24: =U24*V24 -> 0
B25: +6.5 | C25: 1.8 | D25: 0.025 | F25: =E25*D25 -> 0 | H25: 2.6 | I25: 0.029 | K25: =J25*I25 -> 0 | M25: 7.5--8 | N25: 2 | O25: 0.05 | Q25: =P25*O25 -> 0 | S25: +45-70 | T25: 7x5 | U25: 0.75 | W25: =U25*V25 -> 0
B26: +7.0 | C26: 1.9 | D26: 0.03 | F26: =E26*D26 -> 0 | H26: 2.7 | I26: 0.032 | K26: =J26*I26 -> 0 | M26: 8--8.5 | N26: 2.1 | O26: 0.06 | Q26: =P26*O26 -> 0 | S26: +70-90 | T26: 7.4x5 | U26: 0.78 | W26: =U26*V26 -> 0
B27: +7.5 | C27: 2 | D27: 0.035 | F27: =E27*D27 -> 0 | H27: 2.8 | I27: 0.035 | K27: =J27*I27 -> 0 | M27: 8.5--9 | N27: 2.2 | O27: 0.07 | Q27: =P27*O27 -> 0 | S27: +70-90 | T27: 7.8x5 | U27: 0.9 | W27: =U27*V27 -> 0
B28: +8.0 | C28: 2.1 | D28: 0.04 | F28: =E28*D28 -> 0 | H28: 2.9 | I28: 0.038 | K28: =J28*I28 -> 0 | M28: 9--9.5 | N28: 2.3 | O28: 0.08 | Q28: =P28*O28 -> 0 | S28: **** | T28: 8x5 | U28: 1 | W28: =U28*V28 -> 0
B29: +8.5 | C29: 2.2 | D29: 0.045 | F29: =E29*D29 -> 0 | H29: 3 | I29: 0.041 | K29: =J29*I29 -> 0 | M29: 9.5--10 | N29: 2.4 | O29: 0.09 | Q29: =P29*O29 -> 0 | S29: **** | T29: 9x6 | U29: 1.5 | W29: =U29*V29 -> 0
B30: +9.0 | C30: 2.3 | D30: 0.05 | F30: =E30*D30 -> 0 | H30: 3.1 | I30: 0.045 | K30: =J30*I30 -> 0 | M30: 10--10.5 | N30: 2.5 | O30: 0.1 | Q30: =P30*O30 -> 0 | S30: **** | T30: 10x7 | U30: 2 | W30: =U30*V30 -> 0
B31: +9.5 | C31: 2.4 | D31: 0.06 | F31: =E31*D31 -> 0 | H31: 3.2 | I31: 0.05 | K31: =J31*I31 -> 0 | M31: 10.5--11 | N31: 2.6 | O31: 0.11 | Q31: =P31*O31 -> 0 | S31: **** | T31: 11x7 | U31: 2.25 | W31: =U31*V31 -> 0
B32: +10.0 | C32: 2.5 | D32: 0.065 | F32: =E32*D32 -> 0 | H32: 3.3 | I32: 0.052 | K32: =J32*I32 -> 0 | M32: 11--11.5 | N32: 2.7 | O32: 0.123 | Q32: =P32*O32 -> 0 | S32: **** | T32: 12x8 | U32: 3 | W32: =U32*V32 -> 0
B33: +10.5 | C33: 2.6 | D33: 0.07 | F33: =E33*D33 -> 0 | H33: 3.4 | I33: 0.066 | K33: =J33*I33 -> 0 | M33: 11.5--12 | N33: 2.8 | O33: 0.137 | Q33: =P33*O33 -> 0 | S33: **** | T33: 13x9 | U33: 3.5 | W33: =U33*V33 -> 0
B34: +11.0 | C34: 2.7 | D34: 0.08 | F34: =E34*D34 -> 0 | H34: 3.5 | I34: 0.076 | K34: =J34*I34 -> 0 | M34: 12--12.5 | N34: 2.9 | O34: 0.15 | Q34: =P34*O34 -> 0 | S34: **** | T34: 15x10 | U34: 5.5 | W34: =U34*V34 -> 0
B35: +11.5 | C35: 2.8 | D35: 0.09 | F35: =E35*D35 -> 0 | H35: 3.6 | I35: 0.08 | K35: =J35*I35 -> 0 | M35: 12.5--13 | N35: 3 | O35: 0.169 | Q35: =P35*O35 -> 0 | S35: **** | T35: 16x12 | U35: 8.6 | W35: =U35*V35 -> 0
B36: +12.0 | C36: 2.9 | D36: 0.1 | F36: =E36*D36 -> 0 | H36: 3.7 | I36: 0.084 | K36: =J36*I36 -> 0 | M36: 13--13.5 | N36: 3.1 | O36: 0.186 | Q36: =P36*O36 -> 0 | S36: PEAR | V36: =SUM(V9:V35) -> 0 | W36: =SUM(W9:W35) -> 0
B37: +12.5 | C37: 3 | D37: 0.11 | F37: =E37*D37 -> 0 | H37: 3.8 | I37: 0.1 | K37: =J37*I37 -> 0 | M37: 13.5--14 | N37: 3.2 | O37: 0.2 | Q37: =P37*O37 -> 0
B38: +13.0 | C38: 3.1 | D38: 0.12 | F38: =E38*D38 -> 0 | H38: 3.9 | I38: 0.11 | K38: =J38*I38 -> 0 | M38: 14--14.5 | N38: 3.3 | O38: 0.224 | Q38: =P38*O38 -> 0 | S38: MARQUIES
B39: +13.5 | C39: 3.2 | D39: 0.13 | F39: =E39*D39 -> 0 | H39: 4 | I39: 0.122 | K39: =J39*I39 -> 0 | M39: 14.5--15 | N39: 3.4 | O39: 0.25 | Q39: =P39*O39 -> 0 | S39: SIZE | T39: M.M. SIZE | U39: WEIGHT | V39: QTY. | W39: TOTAL
B40: +14.0 | C40: 3.3 | D40: 0.146 | F40: =E40*D40 -> 0 | H40: 4.1 | I40: 0.13 | K40: =J40*I40 -> 0 | M40: 15--15.5 | N40: 3.5 | O40: 0.268 | Q40: =P40*O40 -> 0 | S40: **** | T40: 3x1.5 | U40: 0.03 | W40: =U40*V40 -> 0
B41: +14.5 | C41: 3.4 | D41: 0.153 | F41: =E41*D41 -> 0 | H41: 4.2 | I41: 0.148 | K41: =J41*I41 -> 0 | M41: 15.5--16 | N41: 3.6 | O41: 0.291 | Q41: =P41*O41 -> 0 | S41: **** | T41: 3.3x1.7 | U41: 0.045 | W41: =U41*V41 -> 0
B42: +15.0 | C42: 3.5 | D42: 0.165 | F42: =E42*D42 -> 0 | H42: 4.3 | I42: 0.15 | K42: =J42*I42 -> 0 | M42: 16--16.5 | N42: 3.7 | O42: 0.316 | Q42: =P42*O42 -> 0 | S42: **** | T42: 3.5x1.7 | U42: 0.055 | W42: =U42*V42 -> 0
...

Sheet RING SIZE
B2: INSIDE DIAMETER | C2: US | D2: UK | E2: GERMANY | F2: SPAIN | G2: FRANCE | H2: ITALY | I2: JAPAN
B3: 14 mm | C3: 3 | D3: F | E3: 44 (14.0) | F3: 4 | G3: 44 | H3: 4 | I3: 4
B4: 14.5 mm | C4: 3.5 | D4: G | E4: N/A | F4: N/A | G4: N/A | H4: 5,5 | I4: 5
B5: 15 mm | C5: 4 | D5: H | E5: 47 (15.0) | F5: 6,5 | G5: 46.5 | H5: 7 | I5: 7
B6: 15.3 mm | C6: 4.5 | D6: I | E6: 48 (15.3) | F6: 8 | G6: 48 | H6: 8 | I6: 8
B7: 15.6 mm | C7: 5 | D7: J | E7: 49 (15.6) | F7: 9,5 | G7: 49.5 | H7: 9 | I7: 9
B8: 16.2 mm | C8: 5.5 | D8: K | E8: 51 (16.2) | F8: 10,5 | G8: 50.5 | H8: 10 | I8: 10
B9: 16.6 mm | C9: 6 | D9: L | E9: 52 (16.6) | F9: 12 | G9: 52 | H9: 11 | I9: 11
B10: 16.9 mm | C10: 6.5 | D10: M | E10: 53 (16.9) | F10: 13,5 | G10: 53 | H10: 12,5 | I10: 13
B11: 17.2 mm | C11: 7 | D11: N | E11: 54 (17.2) | F11: 14,5 | G11: 54.5 | H11: 14 | I11: 14
B12: 17.8 mm | C12: 7.5 | D12: O | E12: 56 (17.8) | F12: 16 | G12: 55.5 | H12: 15 | I12: 15
B13: 18.1 mm | C13: 8 | D13: P | E13: 57 (18.1) | F13: 17 | G13: 57 | H13: 16 | I13: 16
B14: 18.5 mm | C14: 8.5 | D14: Q | E14: 58 (18.5) | F14: 18,5 | G14: 58 | H14: 17,5 | I14: 17
B15: 19.1 mm | C15: 9 | D15: R | E15: 60 (19.1) | F15: 20 | G15: 59.5 | H15: 19 | I15: 18
B16: 19.4 mm | C16: 9.5 | D16: S | E16: 61 (19.4) | F16: 21 | G16: 61 | H16: 20 | I16: 19
B17: 19.7 mm | C17: 10 | D17: T | E17: 62 (19.7) | F17: 22,5 | G17: 62 | H17: 21,5 | I17: 20
B18: 20.4 mm | C18: 10.5 | D18: U | E18: 64 (20.4) | F18: 23,5 | G18: 63.5 | H18: 23 | I18: 22
B19: 20.7 mm | C19: 11 | D19: V | E19: 65 (20.7) | F19: 25 | G19: 64.5 | H19: 24 | I19: 23
B20: 21.0 mm | C20: 11.5 | D20: W | E20: 66 (21.0) | F20: 26 | G20: 66 | H20: 25 | I20: 24
B21: 21.6 mm | C21: 12 | D21: X | E21: 68 (21.6) | F21: 27,5 | G21: 67 | H21: 26,5 | I21: 25
B22: 22.0 mm | C22: 12.5 | D22: Y | E22: 69 (22.0) | F22: 29 | G22: 68.5 | H22: 28 | I22: 26
B23: 22.3 mm | C23: 13 | D23: Z | E23: 70 (22.3) | F23: 30 | G23: 69.5 | H23: 28,5 | I23: 27
B24: 22.9 mm | C24: 13.5 | D24: Z+2 | E24: 72 (22.9) | F24: 32 | G24: 71 | H24: 32 | I24: N/A
B25: 23.2 mm | C25: 14 | D25: Z+3 | E25: 73 (23.2) | F25: 33 | G25: 72.5 | H25: 33 | I25: N/A
B26: 23.6 mm | C26: 14.5 | D26: Z+4 | E26: 74 (23.6) | F26: 34,5 | G26: 73.5 | H26: N/A | I26: N/A
C27: 15 | D27: Z+5 | E27: N/A | F27: 35 | G27: 75 | H27: 35 | I27: N/A

Sheet C STONE
A1: PEAR | D1: MARQUIES | G1: OVAL | J1: ROUND | M1: EMERALD | P1: Trillian / CUSION | R1: PRINCESS
A3: M.M. SIZE | B3: WEIGHT | D3: M.M. SIZE | E3: WEIGHT | G3: M.M. SIZE | H3: WEIGHT | J3: M.M. SIZE | K3: WEIGHT | M3: M.M. SIZE | N3: WEIGHT | P3: M.M. SIZE | R3: M.M. SIZE
A4: 5X3 | J4: 1 | M4: 5X3 | P4: 4 | R4: 1.5
A5: 6X4 | D5: 3X1.5 | G5: 5x3 | J5: 1.1 | M5: 6X4 | P5: 6 | R5: 1.75
A6: 7X5 | D6: 4X2 | G6: 6x4 | J6: 1.2 | M6: 7X5 | P6: 7 | R6: 2
A7: 8X6 | D7: 5X2.5 | G7: 7x5 | J7: 1.3 | M7: 8X6 | P7: 8 | R7: 2.25
A8: 9X7 | D8: 6X3 | G8: 8x6 | J8: 1.4 | M8: 9X7 | P8: 9 | R8: 2.5
A9: 10X8 | D9: 7X3.5 | G9: 9x7 | J9: 1.5 | M9: 10X8 | P9: 10 | R9: 3
A10: 11X9 | D10: 8X4 | G10: 10x8 | J10: 1.6 | M10: 11X9 | P10: 11 | R10: 4
A11: 12x10 | D11: 12X6 | G11: 11x9 | J11: 1.7 | M11: 12x10 | P11: 12
G12: 12x10 | J12: 1.8 | M12: 14 X 12
J13: 1.9 | M13: 16 X 12
J14: 2 | M14: 18 X 13
M15: 20 X 15
M16: 25 X 18
A19: KIT | C19: DIA | E19: BUGGET | G19: TAP BUG
A21: M.M. SIZE | C21: M.M. SIZE | E21: M.M. SIZE | G21: M.M. SIZE
A22: 7X4 | C22: 6X4 | E22: 2X1 | G22: 2X1X.8
A23: 8X5 | C23: 7X5 | E23: 3X1.5 | G23: 3X2X1
A24: 10X8 | E24: 3X2 | G24: 4X2X1
A25: 12X10 | E25: 3.5X1.5
E26: 4X2
E27: 6X3
E28: 8X4
B31: Kharbuja | C31: Drop | D31: Ball
B32: 5 mm | C32: 5x3 mm | D32: 3 mm
B33: 6 mm | C33: 6x4 mm | D33: 4 mm
B34: 7 mm | C34: 7x5 mm | D34: 6 mm
B35: 8 mm | C35: 9x6 mm
B36: 9 mm | C36: 12x7 mm
B37: 7x4 mm | C37: 12x9 mm
B38: 10 mm
B39: 10x6 mm

Sheet RING& BRC SIZE
A1: RING SIZE
A2: NO | B2: INDIAN | C2: mm | D2: US | E2: UK | F2: CIRCUMFERENCE | L2: International Ring Size Chart
A3: 1 | B3: 1 | C3: 13 | D3: 1 | F3: 41 | L3: US / Canada | M3: UK / Australia / South Africa | N3: France | O3: Germany / Russia / Ukraine | P3: India / China / Japan / Turkey / Israel | Q3: Italy / Spain / Netherlands / Switzerland
A4: 2 | B4: 2 | C4: 13.4 | D4: 2 | F4: 42 | L4: ½ | M4: A | N4: --- | O4: --- | P4: --- | Q4: ---
A5: 3 | B5: 3 | C5: 13.7 | D5: 2- | F5: 43 | L5: 1 | M5: B | N5: --- | O5: --- | P5: 1 | Q5: ---
A6: 4 | B6: 4 | C6: 14 | D6: 3 | F6: 44 | L6: 1 1/2 | M6: C | N6: --- | O6: --- | P6: --- | Q6: ---
A7: 5 | B7: 5 | C7: 14.3 | D7: 3- | F7: 45 | L7: 2 | M7: D | N7: 41 1/2 | O7: 13 1/4 | P7: 2 | Q7: 1 1/2
A8: 6 | B8: 6 | C8: 14.6 | D8: 3= | F8: 46 | L8: 2 1/4 | M8: D-½ | N8: 42 1/8 | O8: 13 1/2 | P8: --- | Q8: ---
A9: 7 | B9: 7 | C9: 15 | D9: 4 | F9: 47 | H9: 2.1 ANNA | I9: 52.3 | L9: 2 1/2 | M9: E | N9: 42 3/4 | O9: 13 3/4 | P9: 3 | Q9: 2 3/4
A10: 8 | B10: 8 | C10: 15.3 | D10: 4- | F10: 48 | H10: 2.2 ANNA | I10: 53.9 | L10: 2 3/4 | M10: E-½ | N10: 43 3/8 | O10: --- | P10: --- | Q10: 3 3/8
A11: 9 | B11: 9 | C11: 15.6 | D11: 5 | F11: 49 | H11: 2.3 ANNA | I11: 55.5 | L11: 3 | M11: F | N11: 44 | O11: 14 | P11: 4 | Q11: 4
A12: 10 | B12: 10 | C12: 15.9 | D12: 5- | F12: 50 | H12: 2.4 ANNA | I12: 57.1 | L12: 3 1/4 | M12: F-½ | N12: 44 5/8 | O12: 14 1/4 | P12: --- | Q12: 4 5/8
A13: 11 | B13: 11 | C13: 16.2 | D13: 5= | F13: 51 | H13: 2.5 ANNA | I13: 58.7 | L13: 3 1/2 | M13: G | N13: 45 1/4 | O13: 14 1/2 | P13: 5 | Q13: 5 1/4
A14: 12 | B14: 12 | C14: 16.5 | D14: 6 | E14: L | F14: 52 | H14: 2.6 ANNA | I14: 60.3 | L14: 3 3/4 | M14: G-½ | N14: 45 7/8 | O14: 14 3/4 | P14: 6 | Q14: 5 7/8
A15: 13 | B15: 13 | C15: 16.8 | D15: 6- | E15: M | F15: 53 | H15: 2.7 ANNA | I15: 61.9 | L15: 4 | M15: H | N15: 46 1/2 | O15: 15 | P15: 7 | Q15: 6 1/2
A16: 14 | B16: 14 | C16: 17.2 | D16: 7 | E16: N | F16: 54 | H16: 2.8 ANNA | I16: 63.5 | L16: 4 1/4 | M16: H-½ | N16: 47 1/8 | O16: --- | P16: --- | Q16: 7 1/8
A17: 15 | B17: 15 | C17: 17.5 | D17: 7- | F17: 55 | H17: 2.9 ANNA | I17: 65.1 | L17: 4 1/2 | M17: I | N17: 47 3/4 | O17: 15 1/4 | P17: 8 | Q17: 7 3/4
A18: 16 | B18: 16 | C18: 17.8 | D18: 7= | E18: O | F18: 56 | L18: 4 3/4 | M18: J | N18: 48 3/8 | O18: 15 1/2 | P18: --- | Q18: 8 3/8
A19: 17 | B19: 17 | C19: 18.1 | D19: 8 | E19: P | F19: 57 | L19: 5 | M19: J-½ | N19: 49 | O19: 15 3/4 | P19: 9 | Q19: 9
A20: 18 | B20: 18 | C20: 18.4 | D20: 8- | F20: 58 | L20: 5 1/4 | M20: K | N20: 49 5/8 | O20: 16 | P20: --- | Q20: 9 5/8
A21: 19 | B21: 19 | C21: 18.8 | D21: 8= | F21: 59 | H21: 1.5875 mm= 1 aani | L21: 5 1/2 | M21: K-½ | N21: 50 1/4 | O21: 16 1/4 | P21: 10 | Q21: 10 1/4
A22: 20 | B22: 20 | C22: 19.1 | D22: 9 | F22: 60 | H22: 2.54cm=1inch | L22: 5 3/4 | M22: L | N22: 50 7/8 | O22: --- | P22: 11 | Q22: 10 7/8
A23: 21 | B23: 21 | C23: 19.4 | D23: 9- | F23: 61 | H23: 25.4mm=1inch | L23: 6 | M23: L-½ | N23: 51 1/2 | O23: 16 1/2 | P23: 12 | Q23: 11 1/2
A24: 22 | B24: 22 | C24: 19.7 | D24: 10 | F24: 62 | H24: 16 aani=1inch | L24: 6 1/4 | M24: M | N24: 52 1/8 | O24: 16 3/4 | P24: --- | Q24: 12 1/8
A25: 23 | B25: 23 | C25: 20 | D25: 10- | F25: 63 | H25: 1 Soot=3.175 MM | L25: 6 1/2 | M25: M-½ | N25: 52 3/4 | O25: 17 | P25: 13 | Q25: 12 3/4
A26: 24 | B26: 24 | C26: 20.3 | D26: 10= | F26: 64 | H26: INCH CONVERT MM / 3.14 | L26: 6 3/4 | M26: N | N26: 53 3/8 | O26: --- | P26: --- | Q26: 13 3/8
A27: 25 | B27: 25 | C27: 20.6 | D27: 11 | F27: 65 | L27: 7 | M27: O | N27: 54 | O27: 17 1/4 | P27: 14 | Q27: 14
A28: 26 | B28: 26 | C28: 21 | D28: 11- | F28: 66 | H28: DIAMOND WT X 5 = GOLD WT | L28: 7 1/4 | M28: O-½ | N28: 54 5/8 | O28: 17 1/2 | P28: --- | Q28: 14 5/8
A29: 27 | B29: 27 | C29: 21.3 | D29: 12 | F29: 67 | L29: 7 1/2 | M29: P | N29: 55 1/4 | O29: 17 3/4 | P29: 15 | Q29: 15 1/4
A30: 28 | B30: 28 | C30: 21.6 | D30: 12- | F30: 68 | H30: GOLD WT / 5 = DIAMOND WT | L30: 7 3/4 | M30: P-½ | N30: 55 7/8 | O30: 18 | P30: --- | Q30: 15 7/8
A31: 29 | B31: 29 | C31: 22 | D31: 12= | F31: 69 | L31: 8 | M31: Q | N31: 56 1/2 | O31: --- | P31: 16 | Q31: 16 1/2
A32: 30 | B32: 30 | C32: 22.3 | D32: 13 | F32: 70 | H32: GROSS GOLD WT WITH DIAMOND WT | L32: 8 1/4 | M32: Q-½ | N32: 57 1/8 | O32: 18 1/4 | P32: --- | Q32: 17 1/8
A33: 31 | B33: 31 | C33: 22.6 | D33: 13- | F33: 71 | L33: 8 1/2 | M33: R | N33: 57 3/4 | O33: 18 1/2 | P33: 17 | Q33: 17 3/4
A34: 32 | B34: 32 | C34: 22.9 | D34: 13= | F34: 72 | H34: NET GOLD WITHOUT DIAMOND WT | L34: 8 3/4 | M34: R-½ | N34: 58 3/8 | O34: 18 3/4 | P34: --- | Q34: 18 3/8
A35: 33 | B35: 33 | C35: 23.2 | D35: 14 | F35: 73 | L35: 9 | M35: S | N35: 59 | O35: 19 | P35: 18 | Q35: 19
A36: 34 | B36: 34 | C36: 23.5 | D36: 14- | F36: 74 | L36: 9 1/4 | M36: S-½ | N36: 59 5/8 | O36: 19 1/4 | P36: --- | Q36: 19 5/8
A37: 35 | B37: 35 | C37: 23.9 | D37: 15 | F37: 75 | L37: 9 1/2 | M37: --- | N37: 60 1/4 | O37: 19 1/2 | P37: 19 | Q37: 20 1/4
A38: 36 | B38: 36 | C38: 24.2 | D38: 15- | F38: 76 | L38: 9 3/4 | M38: T | N38: 60 7/8 | O38: --- | P38: --- | Q38: 20 7/8
L39: 10 | M39: T-½ | N39: 61 1/2 | O39: 19 3/4 | P39: 20 | Q39: 21 1/2
L40: 10 1/4 | M40: U | N40: 62 1/8 | O40: 20 | P40: 21 | Q40: 22 1/8
...

Sheet COLOR STONE CODE
B2: RM | C2: CODE | E2: SHAPE | F2: CODE | H2: QUALITY | I2: CODE | K2: COLOR | L2: CODE | N2: CUT | O2: CODE | Q2: SUB.CTG | R2: CODE
B3: CUBIC ZIRCONIA | C3: CZ | E3: ROUND | F3: RND | H3: SYNTHETIC BACK RUFF | I3: SBR | K3: RED | L3: RED | N3: BRIOLETTE | O3: BRL | Q3: (CLASSIC) | R3: CLC
E4: OVAL | F4: OVL | H4: SYNTHETIC | I4: SYN | K4: BLUE | L4: BLU | N4: CABOCHON | O4: CAB | Q4: (COCKTAIL) | R4: COK
B5: KALISTA'S COLOR STONE | C5: C | E5: PEAR | F5: PRS | H5: HYDRO BACK RUFF | I5: HBR | K5: GREEN | L5: GRN | N5: REGULAR | O5: REG | Q5: (COPMOSITE) | R5: COM
E6: MARQUISE | F6: MRQ | H6: HYDRO | I6: HYD | K6: BLACK | L6: BLK | N6: PLATE(PLAIN) | O6: PLT | Q6: (COLOR STONE) | R6: CST
B7: PARTY'S COLOR STONE | C7: PC | E7: OCTAGON | F7: OCT | H7: SHELL PEARL | I7: SLP | K7: WHITE | L7: WHT | N7: HALF DRILL | O7: HDR | Q7: (FANCY) | R7: FAN
E8: Bugget | F8: BUG | H8: FRESH W PEARL | I8: FWP | K8: RHODOLITE | L8: ROD | N8: FULL DRILL | O8: FDR | Q8: (FILLIGREE) | R8: FIL
E9: TAPER | F9: TAP | H9: SEMI PRECIOUS | I9: SMP | K9: PINK | L9: PNK | N9: ROSE CUT | O9: RCT | Q9: (FLORAL) | R9: FLR
E10: SQUARE | F10: PRI | H10: ONYX | I10: ONX | K10: YELLOW | L10: YEL | N10: SPECIAL CUT | O10: SPL | Q10: (FLOWER) | R10: FLW
E11: TRIANGLE | F11: TRI | H11: DOUBLET | I11: DBT | K11: GOLDEN | L11: GLD | Q11: (GENERAL) | R11: GEN
E12: TRILLION | F12: TRL | H12: MOTHER OF PEARL | I12: MOP | K12: BLU TOPAZ | L12: BTZ | Q12: (INVISIBILE) | R12: INV
E13: CUSHION | F13: CUS | H13: CHALCEDONY | I13: CAL | K13: AMETHYST | L13: AMT | Q13: (SEMI MOUNTS) | R13: SEM
E14: FANCY | F14: FNC | H14: TOURMALINE | I14: TRM | K14: CITRINE | L14: CTR | Q14: (HEAVY WEIGHT) | R14: HWT
E15: HEART | F15: HRT | H15: PRECIOUS | I15: PRC | K15: RUBY | L15: RUB | Q15: (LIGHT WEIGHT) | R15: LWT
E16: BALL | F16: BAL | K16: EMERALD | L16: EML | Q16: (TRADITIONAL) | R16: TRD
E17: BUTTON | F17: BUT | K17: BLUE SAPPHIRE | L17: BLS | Q17: (DANLINGS) | R17: DAN
E18: DROP | F18: DRO | K18: YELLOW SAPPHIRE | L18: YLS | Q18: (JHUMKA) | R18: JUM
E19: KHARBUJA | F19: KBJ | K19: ORANGE | L19: ORG | Q19: (LOOSE) | R19: LOS
E20: BULLET | F20: BLT | K20: NAVGRAHA | L20: NVG | Q20: (STIFF) | R20: STF
E21: LEAF | F21: LEF | K21: TANZANITE | L21: TNZ | Q21: (J TYPE) | R21: JTY
E22: FLOWER | F22: FLR | Q22: (U TYPE) | R22: UTY
E23: ROSE | F23: ROS | Q23: (Illusion) | R23: ILS
E24: KITE | F24: KIT
E25: DIAMOND | F25: DIA
B27: EXAMPLES FOR REGULAR MEZZARIA COLOR STONE | H27: IF BRIOLETTE
B28: RED | D28: COVLSBRRED | H28: COVLSBRRED-BRL
B29: GREEN | D29: COVLHBRGRN | H29: COVLSBRGRN-BRL
B30: BLUE | D30: COVLSYNBLU | H30: COVLSYNBLU-BRL

Sheet Finding Detail
M7: =L10*20/100 -> 0.04
B8: Plain Pipe Bracelate | F8: Spring Pipe | J8: Ready Chain | O8: Waight Ratio
B9: MM | C9: Inch | D9: WT 18k | F9: MM | G9: Inch | H9: WT 18k | J9: Number | K9: Size | L9: GW 18kt | M9: GW 14kt | O9: Category | P9: Jewel Cad Wt
B10: 2 | C10: 1 | D10: 0.58 | F10: 3.2 | G10: 1 | H10: 1.4 | J10: A4 | K10: 1inch | L10: 0.2 | M10: =L10/18*14 -> 0.15555556
B11: 2.5 | C11: 1 | D11: 0.86 | F11: As 000 MS | G11: 68mm*68mm | H11: 7 Gram | J11: A8 | K11: 1inch | L11: 0.15 | M11: =L11/18*14 -> 0.11666667 | O11: RPT | P11: 12
B12: 3 | C12: 1 | D12: 1.14 | J12: Dia.Cut | K12: 1 Inch | L12: 0.15 | M12: =L12/18*14 -> 0.11666667 | O12: Dcc | P12: 13
B13: 3.5 | C13: 1 | D13: 1.29 | J13: Bid chain | K13: 1 inch | L13: 0.25 | M13: =L13/18*14 -> 0.19444444
A14: 14KT | M14: =L14/18*14 -> 0
B16: Tikali | J16: SS Belt | L16: 1mm Hight
B17: MM | D17: WT
B18: 4.25 | D18: 0.1

Sheet Onex Prl Chart
B3: Onex | G3: Mother Of Parl
B5: Shaph | C5: MM Size | D5: QTY. | E5: TOTAL | G5: Shaph | H5: MM Size | I5: QTY. | J5: TOTAL
B6: SQR | C6: 13 | G6: SQR | H6: 13
B7: SQR | C7: 10 | G7: SQR | H7: 10
B8: RND | C8: 12 | G8: RND | H8: 12
B9: RND | C9: 19 | G9: RND | H9: 19
B10: RND | C10: 20 | G10: RND | H10: 20
B11: RND | C11: 21 | G11: RND | H11: 21
B12: RND | C12: 22 | G12: RND | H12: 22
B13: RND | C13: 21.2 | G13: RND | H13: 23
B14: RND | C14: 35 | G14: Flower | H14: 21.9
G15: Flower | H15: 16
B17: PEAR | D17: =SUM(D9:D16) -> 0 | E17: =SUM(E9:E16) -> 0 | G17: PEAR | I17: =SUM(I9:I16) -> 0 | J17: =SUM(J9:J16) -> 0
B19: Evel Eye
B21: Shaph | C21: Color | D21: MM Size
B22: RND | C22: Opal Blue | D22: 15X3.2
B23: RND | C23: Blue | D23: 20x3.4
B24: RND | C24: Brown | D24: 15x3.2
B25: RND | C25: Blue,Pink | D25: 10X3.2
B26: Flower | C26: Prl Eye | D26: 14x2.6
B27: Flower | C27: Prl Eye | D27: 17.4x2.6 | E27: 17.4x2.6
B28: HART | C28: Opal Pink | D28: 13x13x3.2
B29: PEAR | C29: Opal Org | D29: 16x11x3.2
B30: MRQ | C30: Blue | D30: 14x7x3.3
B31: MRQ | C31: Blue | D31: 16x8.8x3.3
B32: MRQ | C32: Pink | D32: 16x8x3.3
XFD1048576: C:\Program Files (x86)\Adobe\Photoshop 7.0

Sheet OLD C STONE
A2: PEAR | B2: PEAR color stone Ruby / Saphire | H2: Trillian | I2: Trillian | O2: KIT | P2: KIT Ruby / Saphire color stone
B4: M.M. SIZE | C4: WEIGHT | D4: Hight | E4: TOTAL | I4: M.M. SIZE | J4: WEIGHT | K4: Hight | L4: TOTAL | P4: M.M. SIZE | Q4: WEIGHT | R4: Hight | S4: TOTAL
B5: 5X3 | C5: 0.25 | I5: 4 | P5: 7X4
B6: 6X4 | C6: 0.32 | E6: =D6*C6 -> 0 | I6: 6 | P6: 8X5
B7: 7X5 | C7: 0.62 | E7: =D7*C7 -> 0 | I7: 7 | P7: 10X8
B8: 8X6 | C8: 1.06 | E8: =D8*C8 -> 0 | I8: 8 | P8: 12X10
B9: 9X7 | C9: 1.38 | E9: =D9*C9 -> 0 | I9: 9
B10: 10X8 | C10: 2.1 | E10: =D10*C10 -> 0 | I10: 10
B11: 11X9 | C11: 3.02 | E11: =D11*C11 -> 0 | I11: 11 | O11: DIA | P11: DIA Ruby / Saphire color stone
B12: 12x10 | C12: 4.7 | E12: =D12*C12 -> 0 | I12: 12
B13: PEAR | D13: =SUM(D6:D12) -> 0 | E13: =SUM(E6:E12) -> 0 | I13: PEAR | K13: =SUM(K6:K12) -> 0 | L13: =SUM(L6:L12) -> 0 | P13: M.M. SIZE | Q13: WEIGHT | R13: Hight | S13: TOTAL
P14: 6X4
P15: 7X5
A16: MARQUIES | B16: MARQUIES color stone Ruby / Saphire | H16: Cusion | I16: Cusion
B18: M.M. SIZE | C18: WEIGHT | D18: Hight | E18: TOTAL | I18: M.M. SIZE | J18: WEIGHT | K18: Hight | L18: TOTAL
I19: 4 | O19: BUG | P19: BUG Ruby / Saphire color stone
B20: 3X1.5 | C20: 0.19 | E20: =D20*C20 -> 0 | I20: 6
B21: 4X2 | C21: 0.24 | E21: =D21*C21 -> 0 | I21: 7 | P21: M.M. SIZE | Q21: WEIGHT | R21: Hight | S21: TOTAL
B22: 5X2.5 | C22: 0.29 | E22: =D22*C22 -> 0 | I22: 8 | P22: 2X1
B23: 6X3 | C23: 0.41 | E23: =D23*C23 -> 0 | I23: 9 | P23: 3X1.5
B24: 7X3.5 | C24: 0.66 | E24: =D24*C24 -> 0 | I24: 10 | P24: 3X2
B25: 8X4 | C25: 0.98 | E25: =D25*C25 -> 0 | I25: 11 | P25: 3.25X1.5
B26: 12X6 | C26: 1.4 | E26: =D26*C26 -> 0 | I26: 12 | P26: 4X2
C27: 1.92 | E27: =D27*C27 -> 0 | I27: PEAR | K27: =SUM(K20:K26) -> 0 | L27: =SUM(L20:L26) -> 0 | P27: 6X3
P28: 8X4
B29: MARQUIES | D29: =SUM(D19:D28) -> 0 | E29: =SUM(E19:E28) -> 0
O31: TAP BUG | P31: TAP BUG Ruby / Saphire color stone
A32: OVAL | B32: OVAL color stone Ruby / Saphire | H32: EMERALD | I32: EMERALD Ruby / Saphire color stone
P33: M.M. SIZE | Q33: WEIGHT | R33: Hight | S33: TOTAL
B34: M.M. SIZE | C34: WEIGHT | D34: Hight | E34: TOTAL | I34: M.M. SIZE | J34: WEIGHT | K34: Hight | L34: TOTAL | P34: 2X1X.8
I35: 5X3 | J35: 0.86 | L35: =K35*J35 -> 0 | P35: 3X2X1
B36: 5x3 | C36: 0.36 | E36: =C36*D36 -> 0 | I36: 6X4 | J36: 1.47 | L36: =K36*J36 -> 0 | P36: 3X2X1.25
B37: 6x4 | C37: 0.69 | E37: =C37*D37 -> 0 | I37: 7X5 | J37: 1.35 | L37: =K37*J37 -> 0 | P37: 4X2X1
B38: 7x5 | C38: 1.18 | E38: =C38*D38 -> 0 | I38: 8X6 | J38: 3.4 | L38: =K38*J38 -> 0
B39: 8x6 | C39: 1.84 | E39: =C39*D39 -> 0 | I39: 9X7 | J39: 4.8 | L39: =K39*J39 -> 0
B40: 9x7 | C40: 2.72 | E40: =C40*D40 -> 0 | I40: 10X8 | J40: 6.53 | L40: =K40*J40 -> 0
B41: 10x8 | C41: 3.84 | E41: =C41*D41 -> 0 | I41: 11X9 | J41: 8.64 | L41: =K41*J41 -> 0
B42: 11x9 | C42: 6.22 | E42: =C42*D42 -> 0 | I42: 12x10 | J42: 11.76 | L42: =K42*J42 -> 0
B43: 12x10 | C43: 6.91 | E43: =C43*D43 -> 0 | I43: 14 X 12 | J43: 14.11 | L43: =K43*J43 -> 0
B44: OVAL | D44: =SUM(D35:D43) -> 0 | E44: =SUM(E35:E43) -> 0 | I44: 16 X 12 | J44: 18.43 | L44: =K44*J44 -> 0
...
